Workbook

Sheet รวมรายชื่อ
A1: ลำดับ | B1: รหัสนักศึกษา | C1: ชื่อ | D1: ชื่อกลาง | E1: นามสกุล | F1: ภาควิชา | G1: ชื่อ - นามสกุล ก่อน filter
A2: {=_xlfn.SEQUENCE(ROWS(_xlfn.ANCHORARRAY(B2)))} -> 1 | B2: {=_xlfn._xlws.FILTER(_xlfn.VSTACK(Start:End!B9:B2000), _xlfn.VSTACK(Start:End!B9:B2000)<>"")} -> 69070500001 | C2: {=_xlfn.LET(_xlpm.n,_xlfn._xlws.FILTER(_xlfn.VSTACK(Start:End!D9:D2000),_xlfn.VSTACK(Start:End!B9:B2000)<>""),_xlpm.c,TRIM(IF(LEFT(_xlpm.n,6)="นางสาว",MID(_xlpm.n,7,100),IF(LEFT(_xlpm.n,3)="นาย",MID(_xlpm.n,4,100),IF(LEFT(_xlpm.n,3)="นาง",MID(_xlpm.n,4,100),IF(LEFT(UPPER(_xlpm.n),3)="MR.",MID(_xlpm.n,4,100),IF(LEFT(UPPER(_xlpm.n),3)="MS.",MID(_xlpm.n,4,100),IF(LEFT(UPPER(_xlpm.n),4)="MRS.",MID(_xlpm.n,5,100),_xlpm.n))))))),_xlpm.c_clean,SUBSTITUTE(_xlpm.c," ณ "," ณ_"),_xlpm.res,IFERROR(_xlfn.TEXTBEFORE(_xlpm.c_clean," "),_xlpm.c_clean),SUBSTITUTE(_xlpm.res,"_"," "))} -> กรกนก | D2: {=_xlfn.LET(_xlpm.n,_xlfn._xlws.FILTER(_xlfn.VSTACK(Start:End!D9:D2000),_xlfn.VSTACK(Start:End!B9:B2000)<>""),_xlpm.c,TRIM(IF(LEFT(_xlpm.n,6)="นางสาว",MID(_xlpm.n,7,100),IF(LEFT(_xlpm.n,3)="นาย",MID(_xlpm.n,4,100),IF(LEFT(_xlpm.n,3)="นาง",MID(_xlpm.n,4,100),IF(LEFT(UPPER(_xlpm.n),3)="MR.",MID(_xlpm.n,4,100),IF(LEFT(UPPER(_xlpm.n),3)="MS.",MID(_xlpm.n,4,100),IF(LEFT(UPPER(_xlpm.n),4)="MRS.",MID(_xlpm.n,5,100),_xlpm.n))))))),_xlpm.c_clean,SUBSTITUTE(_xlpm.c," ณ "," ณ_"),_xlpm.res,IFERROR(_xlfn.TEXTBEFORE(_xlfn.TEXTAFTER(_xlpm.c_clean," ")," ",-1),""),SUBSTITUTE(_xlpm.res,"_"," "))} | E2: {=_xlfn.LET(_xlpm.n,_xlfn._xlws.FILTER(_xlfn.VSTACK(Start:End!D9:D2000),_xlfn.VSTACK(Start:End!B9:B2000)<>""),_xlpm.c,TRIM(IF(LEFT(_xlpm.n,6)="นางสาว",MID(_xlpm.n,7,100),IF(LEFT(_xlpm.n,3)="นาย",MID(_xlpm.n,4,100),IF(LEFT(_xlpm.n,3)="นาง",MID(_xlpm.n,4,100),IF(LEFT(UPPER(_xlpm.n),3)="MR.",MID(_xlpm.n,4,100),IF(LEFT(UPPER(_xlpm.n),3)="MS.",MID(_xlpm.n,4,100),IF(LEFT(UPPER(_xlpm.n),4)="MRS.",MID(_xlpm.n,5,100),_xlpm.n))))))),_xlpm.c_clean,SUBSTITUTE(_xlpm.c," ณ "," ณ_"),_xlpm.res,IFERROR(_xlfn.TEXTAFTER(_xlpm.c_clean," ",-1),""),SUBSTITUTE(_xlpm.res,"_"," "))} -> จันลาวงศ์ | F2: {=SUBSTITUTE(_xlfn._xlws.FILTER(_xlfn.VSTACK(Start:End!Z9:Z2000), _xlfn.VSTACK(Start:End!B9:B2000)<>""), "ภาควิชา", "")} -> วิศวกรรมเคมี | G2: {=_xlfn._xlws.FILTER(_xlfn.VSTACK(Start:End!D9:D2000),_xlfn.VSTACK(Start:End!B9:B2000)<>"" )} -> นางสาวกรกนก จันลาวงศ์
A3: 2 | B3: 69070500002 | C3: กวินธิดา | E3: จันทร์เทียน | F3: วิศวกรรมเคมี | G3: นางสาวกวินธิดา จันทร์เทียน
A4: 3 | B4: 69070500003 | C4: กานต์ | E4: กิตติกานต์ | F4: วิศวกรรมเคมี | G4: นายกานต์ กิตติกานต์
A5: 4 | B5: 69070500004 | C5: คฑาทิพ | E5: แก้วมณี | F5: วิศวกรรมเคมี | G5: นางสาวคฑาทิพ แก้วมณี
A6: 5 | B6: 69070500005 | C6: จิรัฏฐ์ | E6: ละลี | F6: วิศวกรรมเคมี | G6: นายจิรัฏฐ์ ละลี
A7: 6 | B7: 69070500006 | C7: จิรัฐิพร | E7: สุวรรณทา | F7: วิศวกรรมเคมี | G7: นางสาวจิรัฐิพร สุวรรณทา
A8: 7 | B8: 69070500007 | C8: จิราพร | E8: นิลเกตุแก้ว | F8: วิศวกรรมเคมี | G8: นางสาวจิราพร นิลเกตุแก้ว
A9: 8 | B9: 69070500008 | C9: ชัชนันท์ | E9: คงวุฒิ | F9: วิศวกรรมเคมี | G9: นายชัชนันท์ คงวุฒิ
A10: 9 | B10: 69070500010 | C10: ชุติพงศ์ | E10: เจริญศักดิ์อนันต์ | F10: วิศวกรรมเคมี | G10: นายชุติพงศ์ เจริญศักดิ์อนันต์
A11: 10 | B11: 69070500011 | C11: ญาณินท์ | E11: เพชรแก้ว | F11: วิศวกรรมเคมี | G11: นายญาณินท์ เพชรแก้ว
A12: 11 | B12: 69070500012 | C12: ณัฏฐ์ชญา | E12: เพชรกรณ์ | F12: วิศวกรรมเคมี | G12: นางสาวณัฏฐ์ชญา เพชรกรณ์
A13: 12 | B13: 69070500013 | C13: ณัฐญา | E13: พลเสน | F13: วิศวกรรมเคมี | G13: นางสาวณัฐญา พลเสน
A14: 13 | B14: 69070500014 | C14: ณัฐฏวัฒน์ | E14: ดำรงยิ่งสุภาพ | F14: วิศวกรรมเคมี | G14: นายณัฐฏวัฒน์ ดำรงยิ่งสุภาพ
... A404: 403 | B404: 69070500694 | C404: ภาสวิชญ์ | E404: รอดคง | F404: วิศวกรรมโยธา | G404: นายภาสวิชญ์ รอดคง
A405: 404 | B405: 69070503201 | C405: AUNG | D405: PHONE | E405: CHEIN | F405: วิศวกรรมโยธา | G405: MR.AUNG PHONE CHEIN
A406: 405 | B406: 69070503202 | C406: HEIN | E406: THU | F406: วิศวกรรมโยธา | G406: MR.HEIN THU
A407: 406 | B407: 69070503203 | C407: MAY | D407: MIE MYO | E407: THANT | F407: วิศวกรรมโยธา | G407: MS.MAY MIE MYO THANT
A408: 407 | B408: 69070503204 | C408: SHWE | D408: SIN | E408: LIN | F408: วิศวกรรมโยธา | G408: MS.SHWE SIN LIN
A409: 408 | B409: 69070503205 | C409: SWAM | D409: SAUNG | E409: ZAW | F409: วิศวกรรมโยธา | G409: MR.SWAM SAUNG ZAW
A410: 409 | B410: 69070503206 | C410: THAMUDAYA | E410: TUN | F410: วิศวกรรมโยธา | G410: MS.THAMUDAYA TUN
A411: 410 | B411: 69070503207 | C411: ZUNISBAWITHA | E411: CHIN | F411: วิศวกรรมโยธา | G411: MS.ZUNISBAWITHA CHIN
A412: 411 | B412: 69070503208 | C412: ZWE | D412: PAING | E412: THU | F412: วิศวกรรมโยธา | G412: MR.ZWE PAING THU
A413: 412 | B413: 69070503209 | C413: กฤตภาส | E413: นพวรรณพร | F413: วิศวกรรมโยธา | G413: นายกฤตภาส นพวรรณพร
A414: 413 | B414: 69070503210 | C414: กลวัชร | E414: วิริยนุกูลทรัพย์ | F414: วิศวกรรมโยธา | G414: นายกลวัชร วิริยนุกูลทรัพย์
A415: 414 | B415: 69070503211 | C415: คุณปราบ | E415: กรุณานนท์ | F415: วิศวกรรมโยธา | G415: นายคุณปราบ กรุณานนท์
A416: 415 | B416: 69070503212 | C416: จิตรวรรณ | E416: แก้วกำแหง | F416: วิศวกรรมโยธา | G416: นางสาวจิตรวรรณ แก้วกำแหง
A417: 416 | B417: 69070503213 | C417: จิรทีปต์ | E417: สุดทอง | F417: วิศวกรรมโยธา | G417: นายจิรทีปต์ สุดทอง
A418: 417 | B418: 69070503214 | C418: ณัฐธวัช | E418: โรมรุจนากร | F418: วิศวกรรมโยธา | G418: นายณัฐธวัช โรมรุจนากร
A419: 418 | B419: 69070503215 | C419: ณัฐพล | E419: แก้วเกษร | F419: วิศวกรรมโยธา | G419: นายณัฐพล แก้วเกษร
A420: 419 | B420: 69070503216 | C420: ธนภัทร | E420: ทวีพันธ์ | F420: วิศวกรรมโยธา | G420: นายธนภัทร ทวีพันธ์
A421: 420 | B421: 69070503217 | C421: ธีราทร | E421: สุทธิโพธิ์ | F421: วิศวกรรมโยธา | G421: นายธีราทร สุทธิโพธิ์
A422: 421 | B422: 69070503218 | C422: นิธิวัฒน์ | E422: แก้วไชยา | F422: วิศวกรรมโยธา | G422: นายนิธิวัฒน์ แก้วไชยา
A423: 422 | B423: 69070503219 | C423: ปาณิสรา | E423: เขียวคำ | F423: วิศวกรรมโยธา | G423: นางสาวปาณิสรา เขียวคำ
A424: 423 | B424: 69070503220 | C424: ภาคิน | E424: ธนินวราดล | F424: วิศวกรรมโยธา | G424: นายภาคิน ธนินวราดล
... A428: 427 | B428: 69070503224 | C428: AUNGMIN | E428: KHANT | F428: วิศวกรรมโยธา | G428: MR.AUNGMIN KHANT
A429: 428 | B429: 69070503225 | C429: BHONE | D429: MIN | E429: THANT | F429: วิศวกรรมโยธา | G429: MR.BHONE MIN THANT
A430: 429 | B430: 69070503226 | C430: CHO | D430: THWE | E430: HAN | F430: วิศวกรรมโยธา | G430: MS.CHO THWE HAN
A431: 430 | B431: 69070503227 | C431: EAIN | D431: OO | E431: THAR | F431: วิศวกรรมโยธา | G431: MS.EAIN OO THAR
A432: 431 | B432: 69070503228 | C432: HSUPYAE | D432: PYAE | E432: HMUE | F432: วิศวกรรมโยธา | G432: MS.HSUPYAE PYAE HMUE
...

Sheet Start

Sheet 25540008 ชั้นปี 1(A) รุ่น 2569
A1: ระบบทะเบียน | C1: มหาวิทยาลัยเทคโนโลยีพระจอมเกล้าธนบุรี | J1: วันที่พิมพ์ : 25/06/2569
A2: 455024 | C2: รายงานรายชื่อนักศึกษาแยกตามชั้นปี
C3: ภาคการศึกษา : 3/2568
A4: ระดับปริญญาตรี | F4: คณะวิศวกรรมศาสตร์
A5: ภาควิชาวิศวกรรมเคมี | F5: สาขาวิชาวิศวกรรมเคมี
A6: โครงการหลักสูตร 25540008 วิศวกรรมศาสตรบัณฑิต สาขาวิชาวิศวกรรมเคมี ปริญญาตรี 4 ปี (แผนการเรียน ไทย)
A7: ชั้นปี 1 รุ่นที่เข้าศึกษา 1/2569 ห้อง A อาจารย์ที่ปรึกษา รศ.ดร.ปานจันทร์ ศรีจรูญ
A8: ลำดับ | B8: รหัสนักศึกษา | D8: ชื่อ-สกุล | H8: อาจารย์ที่ปรึกษาเฉพาะบุคคล
A9: 1 | B9: 69070500001 | D9: นางสาวกรกนก จันลาวงศ์ | Z9: =IF(B9="","", A$5) -> ภาควิชาวิศวกรรมเคมี
A10: 2 | B10: 69070500002 | D10: นางสาวกวินธิดา จันทร์เทียน | Z10: =IF(B10="","", A$5) -> ภาควิชาวิศวกรรมเคมี
A11: 3 | B11: 69070500003 | D11: นายกานต์ กิตติกานต์ | Z11: =IF(B11="","", A$5) -> ภาควิชาวิศวกรรมเคมี
A12: 4 | B12: 69070500004 | D12: นางสาวคฑาทิพ แก้วมณี | Z12: =IF(B12="","", A$5) -> ภาควิชาวิศวกรรมเคมี
A13: 5 | B13: 69070500005 | D13: นายจิรัฏฐ์ ละลี | Z13: =IF(B13="","", A$5) -> ภาควิชาวิศวกรรมเคมี
A14: 6 | B14: 69070500006 | D14: นางสาวจิรัฐิพร สุวรรณทา | Z14: =IF(B14="","", A$5) -> ภาควิชาวิศวกรรมเคมี
A15: 7 | B15: 69070500007 | D15: นางสาวจิราพร นิลเกตุแก้ว | Z15: =IF(B15="","", A$5) -> ภาควิชาวิศวกรรมเคมี
A16: 8 | B16: 69070500008 | D16: นายชัชนันท์ คงวุฒิ | Z16: =IF(B16="","", A$5) -> ภาควิชาวิศวกรรมเคมี
A17: 9 | B17: 69070500010 | D17: นายชุติพงศ์ เจริญศักดิ์อนันต์ | Z17: =IF(B17="","", A$5) -> ภาควิชาวิศวกรรมเคมี
A18: 10 | B18: 69070500011 | D18: นายญาณินท์ เพชรแก้ว | Z18: =IF(B18="","", A$5) -> ภาควิชาวิศวกรรมเคมี
A19: 11 | B19: 69070500012 | D19: นางสาวณัฏฐ์ชญา เพชรกรณ์ | Z19: =IF(B19="","", A$5) -> ภาควิชาวิศวกรรมเคมี
A20: 12 | B20: 69070500013 | D20: นางสาวณัฐญา พลเสน | Z20: =IF(B20="","", A$5) -> ภาควิชาวิศวกรรมเคมี
... A52: 44 | B52: 69070500045 | D52: นางสาวกนกวรรณ ยะหัตตะ | Z52: =IF(B52="","", A$5) -> ภาควิชาวิศวกรรมเคมี
Z53: =IF(B53="","", A$5)
Z54: =IF(B54="","", A$5)
Z55: =IF(B55="","", A$5)
Z56: =IF(B56="","", A$5)
Z57: =IF(B57="","", A$5)
Z58: =IF(B58="","", A$5)
Z59: =IF(B59="","", A$5)
Z60: =IF(B60="","", A$5)
Z61: =IF(B61="","", A$5)
Z62: =IF(B62="","", A$5)
Z63: =IF(B63="","", A$5)
Z64: =IF(B64="","", A$5)
... Z1863: =IF(B1863="","", A$5)

Sheet 25540008 ชั้นปี 1(B) รุ่น 2569
A1: ระบบทะเบียน | C1: มหาวิทยาลัยเทคโนโลยีพระจอมเกล้าธนบุรี | J1: วันที่พิมพ์ : 25/06/2569
A2: 455024 | C2: รายงานรายชื่อนักศึกษาแยกตามชั้นปี
C3: ภาคการศึกษา : 3/2568
A4: ระดับปริญญาตรี | F4: คณะวิศวกรรมศาสตร์
A5: ภาควิชาวิศวกรรมเคมี | F5: สาขาวิชาวิศวกรรมเคมี
A6: โครงการหลักสูตร 25540008 วิศวกรรมศาสตรบัณฑิต สาขาวิชาวิศวกรรมเคมี ปริญญาตรี 4 ปี (แผนการเรียน ไทย)
A7: ชั้นปี 1 รุ่นที่เข้าศึกษา 1/2569 ห้อง B อาจารย์ที่ปรึกษา ผศ.ดร.ชุติมา ก้องวโรดม
A8: ลำดับ | B8: รหัสนักศึกษา | D8: ชื่อ-สกุล | H8: อาจารย์ที่ปรึกษาเฉพาะบุคคล
A9: 1 | B9: 69070500046 | D9: นายกมลภพ เชื้อไทย | Z9: =IF(B9="","", A$5) -> ภาควิชาวิศวกรรมเคมี
A10: 2 | B10: 69070500047 | D10: นางสาวกาญจนรัตน์ แสวงทรัพย์ | Z10: =IF(B10="","", A$5) -> ภาควิชาวิศวกรรมเคมี
A11: 3 | B11: 69070500048 | D11: นายกิตติภณ มีสาวงษ์ | Z11: =IF(B11="","", A$5) -> ภาควิชาวิศวกรรมเคมี
A12: 4 | B12: 69070500049 | D12: นางสาวโกลัญญา เกิดรอด | Z12: =IF(B12="","", A$5) -> ภาควิชาวิศวกรรมเคมี
A13: 5 | B13: 69070500050 | D13: นางสาวจิรัชญา พรมมา | Z13: =IF(B13="","", A$5) -> ภาควิชาวิศวกรรมเคมี
A14: 6 | B14: 69070500051 | D14: นางสาวจิรัศยา เนตรอรุณ | Z14: =IF(B14="","", A$5) -> ภาควิชาวิศวกรรมเคมี
A15: 7 | B15: 69070500052 | D15: นางสาวชญาดา กองพร | Z15: =IF(B15="","", A$5) -> ภาควิชาวิศวกรรมเคมี
A16: 8 | B16: 69070500053 | D16: นายชินพงค์ อำภารส | Z16: =IF(B16="","", A$5) -> ภาควิชาวิศวกรรมเคมี
A17: 9 | B17: 69070500054 | D17: นางสาวญาณิกา จิโนวงษ์ | Z17: =IF(B17="","", A$5) -> ภาควิชาวิศวกรรมเคมี
A18: 10 | B18: 69070500055 | D18: นายไตยรัตน์ วิทยาปัญญานนท์ | Z18: =IF(B18="","", A$5) -> ภาควิชาวิศวกรรมเคมี
A19: 11 | B19: 69070500056 | D19: นางสาวทิพจิตตา สุวรรณชัย | Z19: =IF(B19="","", A$5) -> ภาควิชาวิศวกรรมเคมี
A20: 12 | B20: 69070500057 | D20: นายธนภัทร สร้อยโยธา | Z20: =IF(B20="","", A$5) -> ภาควิชาวิศวกรรมเคมี
... A51: 43 | B51: 69070500088 | D51: นางสาวอภิชญา รื่นรวย | Z51: =IF(B51="","", A$5) -> ภาควิชาวิศวกรรมเคมี
Z52: =IF(B52="","", A$5)
Z53: =IF(B53="","", A$5)
Z54: =IF(B54="","", A$5)
Z55: =IF(B55="","", A$5)
Z56: =IF(B56="","", A$5)
Z57: =IF(B57="","", A$5)
Z58: =IF(B58="","", A$5)
Z59: =IF(B59="","", A$5)
Z60: =IF(B60="","", A$5)
Z61: =IF(B61="","", A$5)
Z62: =IF(B62="","", A$5)
Z63: =IF(B63="","", A$5)
... Z1863: =IF(B1863="","", A$5)

Sheet 25540019 ชั้นปี 1(A) รุ่น 2569
A1: ระบบทะเบียน | C1: มหาวิทยาลัยเทคโนโลยีพระจอมเกล้าธนบุรี | J1: วันที่พิมพ์ : 25/06/2569
A2: 455024 | C2: รายงานรายชื่อนักศึกษาแยกตามชั้นปี
C3: ภาคการศึกษา : 3/2568
A4: ระดับปริญญาตรี | F4: คณะวิศวกรรมศาสตร์
A5: ภาควิชาวิศวกรรมเครื่องกล | F5: สาขาวิชาวิศวกรรมเครื่องกล
A6: โครงการหลักสูตร 25540019 วิศวกรรมศาสตรบัณฑิต สาขาวิชาวิศวกรรมเครื่องกล ปริญญาตรี 4 ปี
A7: ชั้นปี 1 รุ่นที่เข้าศึกษา 1/2569 ห้อง A อาจารย์ที่ปรึกษา ผศ.ดร.ญาณิน สุขใจ, รศ.ดร.พชรพิชญ์ พรหมอุปถัมภ์
A8: ลำดับ | B8: รหัสนักศึกษา | D8: ชื่อ-สกุล | H8: อาจารย์ที่ปรึกษาเฉพาะบุคคล
A9: 1 | B9: 69070500201 | D9: นางสาวกชพร ร่มรื่น | Z9: =IF(B9="","", A$5) -> ภาควิชาวิศวกรรมเครื่องกล
A10: 2 | B10: 69070500202 | D10: นายก้องภพ กวยานนท์ | Z10: =IF(B10="","", A$5) -> ภาควิชาวิศวกรรมเครื่องกล
A11: 3 | B11: 69070500203 | D11: นายกันตวัฒน์ กิ่งมณี | Z11: =IF(B11="","", A$5) -> ภาควิชาวิศวกรรมเครื่องกล
A12: 4 | B12: 69070500204 | D12: นางสาวกานต์พิชชา แสงศรี | Z12: =IF(B12="","", A$5) -> ภาควิชาวิศวกรรมเครื่องกล
A13: 5 | B13: 69070500205 | D13: นายเกจิชนะ จิระวงศ์ไพศาล | Z13: =IF(B13="","", A$5) -> ภาควิชาวิศวกรรมเครื่องกล
A14: 6 | B14: 69070500206 | D14: นายคิมหันต์ แซ่หลี | Z14: =IF(B14="","", A$5) -> ภาควิชาวิศวกรรมเครื่องกล
A15: 7 | B15: 69070500207 | D15: นายจิระวิน ถิรทิตสกุล | Z15: =IF(B15="","", A$5) -> ภาควิชาวิศวกรรมเครื่องกล
A16: 8 | B16: 69070500208 | D16: นางสาวจิราภรณ์ พิมพ์ทอง | Z16: =IF(B16="","", A$5) -> ภาควิชาวิศวกรรมเครื่องกล
A17: 9 | B17: 69070500209 | D17: นายจิรายุ ภูผาผุด | Z17: =IF(B17="","", A$5) -> ภาควิชาวิศวกรรมเครื่องกล
A18: 10 | B18: 69070500210 | D18: นายชยภัทร ตลึงจิตร | Z18: =IF(B18="","", A$5) -> ภาควิชาวิศวกรรมเครื่องกล
A19: 11 | B19: 69070500211 | D19: นายชยานนท์ สลีแดง | Z19: =IF(B19="","", A$5) -> ภาควิชาวิศวกรรมเครื่องกล
A20: 12 | B20: 69070500212 | D20: นายชลธี สักขาพรหม | Z20: =IF(B20="","", A$5) -> ภาควิชาวิศวกรรมเครื่องกล
... A48: 40 | B48: 69070500241 | D48: นางสาวปริดา สุดกล้า | Z48: =IF(B48="","", A$5) -> ภาควิชาวิศวกรรมเครื่องกล
Z49: =IF(B49="","", A$5)
Z50: =IF(B50="","", A$5)
Z51: =IF(B51="","", A$5)
Z52: =IF(B52="","", A$5)
Z53: =IF(B53="","", A$5)
Z54: =IF(B54="","", A$5)
Z55: =IF(B55="","", A$5)
Z56: =IF(B56="","", A$5)
Z57: =IF(B57="","", A$5)
Z58: =IF(B58="","", A$5)
Z59: =IF(B59="","", A$5)
Z60: =IF(B60="","", A$5)
... Z1863: =IF(B1863="","", A$5)

Sheet 25540019 ชั้นปี 1(B) รุ่น 2569
A1: ระบบทะเบียน | C1: มหาวิทยาลัยเทคโนโลยีพระจอมเกล้าธนบุรี | J1: วันที่พิมพ์ : 25/06/2569
A2: 455024 | C2: รายงานรายชื่อนักศึกษาแยกตามชั้นปี
C3: ภาคการศึกษา : 3/2568
A4: ระดับปริญญาตรี | F4: คณะวิศวกรรมศาสตร์
A5: ภาควิชาวิศวกรรมเครื่องกล | F5: สาขาวิชาวิศวกรรมเครื่องกล
A6: โครงการหลักสูตร 25540019 วิศวกรรมศาสตรบัณฑิต สาขาวิชาวิศวกรรมเครื่องกล ปริญญาตรี 4 ปี
A7: ชั้นปี 1 รุ่นที่เข้าศึกษา 1/2569 ห้อง B อาจารย์ที่ปรึกษา รศ.ดร.ชวิน จันทรเสนาวงศ์, ผศ.ดร.ปิยธิดา ไตรนุรักษ์ แก้วจินดา
A8: ลำดับ | B8: รหัสนักศึกษา | D8: ชื่อ-สกุล | H8: อาจารย์ที่ปรึกษาเฉพาะบุคคล
A9: 1 | B9: 69070500242 | D9: นายปัญจพล โคตรชารี | Z9: =IF(B9="","", A$5) -> ภาควิชาวิศวกรรมเครื่องกล
A10: 2 | B10: 69070500243 | D10: นายปัญญากร เบญจเตชะ | Z10: =IF(B10="","", A$5) -> ภาควิชาวิศวกรรมเครื่องกล
A11: 3 | B11: 69070500244 | D11: นายพชรมงคล ทองปลิว | Z11: =IF(B11="","", A$5) -> ภาควิชาวิศวกรรมเครื่องกล
A12: 4 | B12: 69070500245 | D12: นายพฤกษ์ พักรกรึก | Z12: =IF(B12="","", A$5) -> ภาควิชาวิศวกรรมเครื่องกล
A13: 5 | B13: 69070500246 | D13: นายพศิน หล่อพงศ์ไพบูลย์ | Z13: =IF(B13="","", A$5) -> ภาควิชาวิศวกรรมเครื่องกล
A14: 6 | B14: 69070500247 | D14: นายพัชรพล สุขเจริญธนานนท์ | Z14: =IF(B14="","", A$5) -> ภาควิชาวิศวกรรมเครื่องกล
A15: 7 | B15: 69070500248 | D15: นายพีรณัฐ ทองพรมราช | Z15: =IF(B15="","", A$5) -> ภาควิชาวิศวกรรมเครื่องกล
A16: 8 | B16: 69070500249 | D16: นายพีรภาส ไพศาล | Z16: =IF(B16="","", A$5) -> ภาควิชาวิศวกรรมเครื่องกล
A17: 9 | B17: 69070500250 | D17: นายพีรวิชญ์ เทพแก้ว | Z17: =IF(B17="","", A$5) -> ภาควิชาวิศวกรรมเครื่องกล
A18: 10 | B18: 69070500251 | D18: นางสาวภัทราพร กาศรัมย์ | Z18: =IF(B18="","", A$5) -> ภาควิชาวิศวกรรมเครื่องกล
A19: 11 | B19: 69070500252 | D19: นายภาสวุฒิ อัศวกิตติพร | Z19: =IF(B19="","", A$5) -> ภาควิชาวิศวกรรมเครื่องกล
A20: 12 | B20: 69070500253 | D20: นายภูธน โสภะถา | Z20: =IF(B20="","", A$5) -> ภาควิชาวิศวกรรมเครื่องกล
... A48: 40 | B48: 69070500282 | D48: นายณัฐภัทร วงษ์อนันท์ | Z48: =IF(B48="","", A$5) -> ภาควิชาวิศวกรรมเครื่องกล
Z49: =IF(B49="","", A$5)
Z50: =IF(B50="","", A$5)
Z51: =IF(B51="","", A$5)
Z52: =IF(B52="","", A$5)
Z53: =IF(B53="","", A$5)
Z54: =IF(B54="","", A$5)
Z55: =IF(B55="","", A$5)
Z56: =IF(B56="","", A$5)
Z57: =IF(B57="","", A$5)
Z58: =IF(B58="","", A$5)
Z59: =IF(B59="","", A$5)
Z60: =IF(B60="","", A$5)
... Z1863: =IF(B1863="","", A$5)

Sheet 25540019 ชั้นปี 1(C) รุ่น 2569
A1: ระบบทะเบียน | C1: มหาวิทยาลัยเทคโนโลยีพระจอมเกล้าธนบุรี | J1: วันที่พิมพ์ : 25/06/2569
A2: 455024 | C2: รายงานรายชื่อนักศึกษาแยกตามชั้นปี
C3: ภาคการศึกษา : 3/2568
A4: ระดับปริญญาตรี | F4: คณะวิศวกรรมศาสตร์
A5: ภาควิชาวิศวกรรมเครื่องกล | F5: สาขาวิชาวิศวกรรมเครื่องกล
A6: โครงการหลักสูตร 25540019 วิศวกรรมศาสตรบัณฑิต สาขาวิชาวิศวกรรมเครื่องกล ปริญญาตรี 4 ปี
A7: ชั้นปี 1 รุ่นที่เข้าศึกษา 1/2569 ห้อง C อาจารย์ที่ปรึกษา ผศ.ดร.สโรช ไทรเมฆ, ผศ.ดร.สาทิสส์ ทรงชน
A8: ลำดับ | B8: รหัสนักศึกษา | D8: ชื่อ-สกุล | H8: อาจารย์ที่ปรึกษาเฉพาะบุคคล
A9: 1 | B9: 69070500283 | D9: นางสาวณิชนันทร์ อภิกิตตินันท์ | Z9: =IF(B9="","", A$5) -> ภาควิชาวิศวกรรมเครื่องกล
A10: 2 | B10: 69070500284 | D10: นายเตวิช ศรีพัฒนธาดากุล | Z10: =IF(B10="","", A$5) -> ภาควิชาวิศวกรรมเครื่องกล
A11: 3 | B11: 69070500285 | D11: นายธนัทฤทธิ์ ชัยนาม | Z11: =IF(B11="","", A$5) -> ภาควิชาวิศวกรรมเครื่องกล
A12: 4 | B12: 69070500286 | D12: นายธัญพิสิษต์ นวลสาลี | Z12: =IF(B12="","", A$5) -> ภาควิชาวิศวกรรมเครื่องกล
A13: 5 | B13: 69070500287 | D13: นายธัญวรัตม์ รุ่งสวัสดิ์ | Z13: =IF(B13="","", A$5) -> ภาควิชาวิศวกรรมเครื่องกล
A14: 6 | B14: 69070500288 | D14: นายนิสสรณ์ พงศ์สุทธินันท์ | Z14: =IF(B14="","", A$5) -> ภาควิชาวิศวกรรมเครื่องกล
A15: 7 | B15: 69070500289 | D15: นายพรเทพา ศึกษา | Z15: =IF(B15="","", A$5) -> ภาควิชาวิศวกรรมเครื่องกล
A16: 8 | B16: 69070500290 | D16: นายพัสกร สงครามศรี | Z16: =IF(B16="","", A$5) -> ภาควิชาวิศวกรรมเครื่องกล
A17: 9 | B17: 69070500291 | D17: นายพีรภาส จันทร์แดง | Z17: =IF(B17="","", A$5) -> ภาควิชาวิศวกรรมเครื่องกล
A18: 10 | B18: 69070500292 | D18: นายเพลงไทย พรมมานนท์ | Z18: =IF(B18="","", A$5) -> ภาควิชาวิศวกรรมเครื่องกล
A19: 11 | B19: 69070500293 | D19: นางสาวภัทรานิษฐ์ มนทอง | Z19: =IF(B19="","", A$5) -> ภาควิชาวิศวกรรมเครื่องกล
A20: 12 | B20: 69070500294 | D20: นายศิริวัชร์ จิตแจ่ม | Z20: =IF(B20="","", A$5) -> ภาควิชาวิศวกรรมเครื่องกล
... A50: 42 | B50: 69070500324 | D50: นายเอื้ออังกูร จุลลวาทีเลิศ | Z50: =IF(B50="","", A$5) -> ภาควิชาวิศวกรรมเครื่องกล
Z51: =IF(B51="","", A$5)
Z52: =IF(B52="","", A$5)
Z53: =IF(B53="","", A$5)
Z54: =IF(B54="","", A$5)
Z55: =IF(B55="","", A$5)
Z56: =IF(B56="","", A$5)
Z57: =IF(B57="","", A$5)
Z58: =IF(B58="","", A$5)
Z59: =IF(B59="","", A$5)
Z60: =IF(B60="","", A$5)
Z61: =IF(B61="","", A$5)
Z62: =IF(B62="","", A$5)
... Z1863: =IF(B1863="","", A$5)

Sheet 25540031 ชั้นปี 1(A) รุ่น 2569
A1: ระบบทะเบียน | C1: มหาวิทยาลัยเทคโนโลยีพระจอมเกล้าธนบุรี | J1: วันที่พิมพ์ : 25/06/2569
A2: 455024 | C2: รายงานรายชื่อนักศึกษาแยกตามชั้นปี
C3: ภาคการศึกษา : 3/2568
A4: ระดับปริญญาตรี | F4: คณะวิศวกรรมศาสตร์
A5: ภาควิชาวิศวกรรมไฟฟ้า | F5: สาขาวิชาวิศวกรรมไฟฟ้า
A6: โครงการหลักสูตร 25540031 วิศวกรรมศาสตรบัณฑิต สาขาวิชาวิศวกรรมไฟฟ้า ปริญญาตรี 4 ปี
A7: ชั้นปี 1 รุ่นที่เข้าศึกษา 1/2569 ห้อง A อาจารย์ที่ปรึกษา ผศ.ดร.เอกชัย มุจจลินท์วิมุติ
A8: ลำดับ | B8: รหัสนักศึกษา | D8: ชื่อ-สกุล | H8: อาจารย์ที่ปรึกษาเฉพาะบุคคล
A9: 1 | B9: 69070500401 | D9: นายกันต์พฤกษ์ กิจเจริญวงศ์ | Z9: =IF(B9="","", A$5) -> ภาควิชาวิศวกรรมไฟฟ้า
A10: 2 | B10: 69070500402 | D10: นายกันตวรวัฒน์ ดวงบุญ | Z10: =IF(B10="","", A$5) -> ภาควิชาวิศวกรรมไฟฟ้า
A11: 3 | B11: 69070500403 | D11: นางสาวกัลย์สุดา เนาวพนานนท์ | Z11: =IF(B11="","", A$5) -> ภาควิชาวิศวกรรมไฟฟ้า
A12: 4 | B12: 69070500404 | D12: นายกิตติพงศ์ เชื้อหลง | Z12: =IF(B12="","", A$5) -> ภาควิชาวิศวกรรมไฟฟ้า
A13: 5 | B13: 69070500405 | D13: นายขจรเดช แก้วชาญศิลป์ | Z13: =IF(B13="","", A$5) -> ภาควิชาวิศวกรรมไฟฟ้า
A14: 6 | B14: 69070500406 | D14: นายจิรพัส ต่อมยิ้ม | Z14: =IF(B14="","", A$5) -> ภาควิชาวิศวกรรมไฟฟ้า
A15: 7 | B15: 69070500407 | D15: นายชนาภัทร เตชะธนาเลิศ | Z15: =IF(B15="","", A$5) -> ภาควิชาวิศวกรรมไฟฟ้า
A16: 8 | B16: 69070500408 | D16: นายชวนากร ทิพย์จำนงค์ | Z16: =IF(B16="","", A$5) -> ภาควิชาวิศวกรรมไฟฟ้า
A17: 9 | B17: 69070500409 | D17: นายชอช้าง อรุณวรรธนะ | Z17: =IF(B17="","", A$5) -> ภาควิชาวิศวกรรมไฟฟ้า
A18: 10 | B18: 69070500410 | D18: นายชารอฟุดดีน ทับโทน | Z18: =IF(B18="","", A$5) -> ภาควิชาวิศวกรรมไฟฟ้า
A19: 11 | B19: 69070500411 | D19: นายเชิดศักดิ์ จันทร์โพธิ์ | Z19: =IF(B19="","", A$5) -> ภาควิชาวิศวกรรมไฟฟ้า
A20: 12 | B20: 69070500412 | D20: นายณภัทร หลากสุขถม | Z20: =IF(B20="","", A$5) -> ภาควิชาวิศวกรรมไฟฟ้า
... A58: 50 | B58: 69070500450 | D58: นายวสันต์ สุขมหานนท์ | Z58: =IF(B58="","", A$5) -> ภาควิชาวิศวกรรมไฟฟ้า
Z59: =IF(B59="","", A$5)
Z60: =IF(B60="","", A$5)
Z61: =IF(B61="","", A$5)
Z62: =IF(B62="","", A$5)
Z63: =IF(B63="","", A$5)
Z64: =IF(B64="","", A$5)
Z65: =IF(B65="","", A$5)
Z66: =IF(B66="","", A$5)
Z67: =IF(B67="","", A$5)
Z68: =IF(B68="","", A$5)
Z69: =IF(B69="","", A$5)
Z70: =IF(B70="","", A$5)
... Z1863: =IF(B1863="","", A$5)

Sheet 25540031 ชั้นปี 1(B) รุ่น 2569
A1: ระบบทะเบียน | C1: มหาวิทยาลัยเทคโนโลยีพระจอมเกล้าธนบุรี | J1: วันที่พิมพ์ : 25/06/2569
A2: 455024 | C2: รายงานรายชื่อนักศึกษาแยกตามชั้นปี
C3: ภาคการศึกษา : 3/2568
A4: ระดับปริญญาตรี | F4: คณะวิศวกรรมศาสตร์
A5: ภาควิชาวิศวกรรมไฟฟ้า | F5: สาขาวิชาวิศวกรรมไฟฟ้า
A6: โครงการหลักสูตร 25540031 วิศวกรรมศาสตรบัณฑิต สาขาวิชาวิศวกรรมไฟฟ้า ปริญญาตรี 4 ปี
A7: ชั้นปี 1 รุ่นที่เข้าศึกษา 1/2569 ห้อง B อาจารย์ที่ปรึกษา อ.ธิระศักดิ์ เสภากล่อม
A8: ลำดับ | B8: รหัสนักศึกษา | D8: ชื่อ-สกุล | H8: อาจารย์ที่ปรึกษาเฉพาะบุคคล
A9: 1 | B9: 69070500451 | D9: นายวิชญ์พล เฉลิมรัตนาพร | Z9: =IF(B9="","", A$5) -> ภาควิชาวิศวกรรมไฟฟ้า
A10: 2 | B10: 69070500452 | D10: นายวิชยุตม์ แซ่ลิ้ม | Z10: =IF(B10="","", A$5) -> ภาควิชาวิศวกรรมไฟฟ้า
A11: 3 | B11: 69070500453 | D11: นายวิบูลย์ธรรม ทวีคงศักดิ์สกุล | Z11: =IF(B11="","", A$5) -> ภาควิชาวิศวกรรมไฟฟ้า
A12: 4 | B12: 69070500454 | D12: นายวีรภัทร์ จรัสโสภณ | Z12: =IF(B12="","", A$5) -> ภาควิชาวิศวกรรมไฟฟ้า
A13: 5 | B13: 69070500455 | D13: นางสาวศรัณย์พร ธนเจริญประดิษฐ์ | Z13: =IF(B13="","", A$5) -> ภาควิชาวิศวกรรมไฟฟ้า
A14: 6 | B14: 69070500456 | D14: นายศิริพงษ์ บุญเชื้อ | Z14: =IF(B14="","", A$5) -> ภาควิชาวิศวกรรมไฟฟ้า
A15: 7 | B15: 69070500457 | D15: นายศิวัช ศิริสวัสดิ์ | Z15: =IF(B15="","", A$5) -> ภาควิชาวิศวกรรมไฟฟ้า
A16: 8 | B16: 69070500458 | D16: นายษุบิณธ เดชอุดม | Z16: =IF(B16="","", A$5) -> ภาควิชาวิศวกรรมไฟฟ้า
A17: 9 | B17: 69070500459 | D17: นายสรวิชญ์ เขมะจารัง | Z17: =IF(B17="","", A$5) -> ภาควิชาวิศวกรรมไฟฟ้า
A18: 10 | B18: 69070500460 | D18: นายสุรวีร์ ศิริโยธา | Z18: =IF(B18="","", A$5) -> ภาควิชาวิศวกรรมไฟฟ้า
A19: 11 | B19: 69070500461 | D19: นางสาวสุรัสวดี สิทธิศักดิ์ | Z19: =IF(B19="","", A$5) -> ภาควิชาวิศวกรรมไฟฟ้า
A20: 12 | B20: 69070500462 | D20: นางสาวอริสรา วานิชเจริญนาน | Z20: =IF(B20="","", A$5) -> ภาควิชาวิศวกรรมไฟฟ้า
... A58: 50 | B58: 69070500500 | D58: นายวีระภัทร เขียวคำรพ | Z58: =IF(B58="","", A$5) -> ภาควิชาวิศวกรรมไฟฟ้า
Z59: =IF(B59="","", A$5)
Z60: =IF(B60="","", A$5)
Z61: =IF(B61="","", A$5)
Z62: =IF(B62="","", A$5)
Z63: =IF(B63="","", A$5)
Z64: =IF(B64="","", A$5)
Z65: =IF(B65="","", A$5)
Z66: =IF(B66="","", A$5)
Z67: =IF(B67="","", A$5)
Z68: =IF(B68="","", A$5)
Z69: =IF(B69="","", A$5)
Z70: =IF(B70="","", A$5)
... Z1863: =IF(B1863="","", A$5)

Sheet 25540045 ชั้นปี 1(A) รุ่น 2569
A1: ระบบทะเบียน | C1: มหาวิทยาลัยเทคโนโลยีพระจอมเกล้าธนบุรี | J1: วันที่พิมพ์ : 25/06/2569
A2: 455024 | C2: รายงานรายชื่อนักศึกษาแยกตามชั้นปี
C3: ภาคการศึกษา : 3/2568
A4: ระดับปริญญาตรี | F4: คณะวิศวกรรมศาสตร์
A5: ภาควิชาวิศวกรรมโยธา | F5: สาขาวิชาวิศวกรรมโยธา
A6: โครงการหลักสูตร 25540045 วิศวกรรมศาสตรบัณฑิต สาขาวิชาวิศวกรรมโยธา ปริญญาตรี 4 ปี
A7: ชั้นปี 1 รุ่นที่เข้าศึกษา 1/2569 ห้อง A อาจารย์ที่ปรึกษา ดร.กสาน จันทร์โต
A8: ลำดับ | B8: รหัสนักศึกษา | D8: ชื่อ-สกุล | H8: อาจารย์ที่ปรึกษาเฉพาะบุคคล
A9: 1 | B9: 69070500601 | D9: นางสาวกชกร สุขเสริมศาล | Z9: =IF(B9="","", A$5) -> ภาควิชาวิศวกรรมโยธา
A10: 2 | B10: 69070500602 | D10: นายกรวิชญ์ เลี้ยงพรม | Z10: =IF(B10="","", A$5) -> ภาควิชาวิศวกรรมโยธา
A11: 3 | B11: 69070500603 | D11: นายกิตติธัช ทรัพย์บาง | Z11: =IF(B11="","", A$5) -> ภาควิชาวิศวกรรมโยธา
A12: 4 | B12: 69070500604 | D12: นายเกษม ปฐมโอสถ | Z12: =IF(B12="","", A$5) -> ภาควิชาวิศวกรรมโยธา
A13: 5 | B13: 69070500605 | D13: นายไกรวิน วงศ์เมือง | Z13: =IF(B13="","", A$5) -> ภาควิชาวิศวกรรมโยธา
A14: 6 | B14: 69070500606 | D14: นายคณาธิป พูลสวัสดิ์ | Z14: =IF(B14="","", A$5) -> ภาควิชาวิศวกรรมโยธา
A15: 7 | B15: 69070500607 | D15: นายคะนอง คนทันทส์ | Z15: =IF(B15="","", A$5) -> ภาควิชาวิศวกรรมโยธา
A16: 8 | B16: 69070500608 | D16: นายจารุกิตติ์ สุขสุผิว | Z16: =IF(B16="","", A$5) -> ภาควิชาวิศวกรรมโยธา
A17: 9 | B17: 69070500609 | D17: นางสาวจิตราเพชร ทินนา | Z17: =IF(B17="","", A$5) -> ภาควิชาวิศวกรรมโยธา
A18: 10 | B18: 69070500610 | D18: นางสาวจินต์จุฑา ธาดาวุธ | Z18: =IF(B18="","", A$5) -> ภาควิชาวิศวกรรมโยธา
A19: 11 | B19: 69070500611 | D19: นายจิรพัส บุญเลิศ | Z19: =IF(B19="","", A$5) -> ภาควิชาวิศวกรรมโยธา
A20: 12 | B20: 69070500612 | D20: นายชนุตม์ พงษ์สิงห์จันทร์ | Z20: =IF(B20="","", A$5) -> ภาควิชาวิศวกรรมโยธา
... A55: 47 | B55: 69070500647 | D55: นางสาวภัทรวรรณ เจริญพร | Z55: =IF(B55="","", A$5) -> ภาควิชาวิศวกรรมโยธา
Z56: =IF(B56="","", A$5)
Z57: =IF(B57="","", A$5)
Z58: =IF(B58="","", A$5)
Z59: =IF(B59="","", A$5)
Z60: =IF(B60="","", A$5)
Z61: =IF(B61="","", A$5)
Z62: =IF(B62="","", A$5)
Z63: =IF(B63="","", A$5)
Z64: =IF(B64="","", A$5)
Z65: =IF(B65="","", A$5)
Z66: =IF(B66="","", A$5)
Z67: =IF(B67="","", A$5)
... Z1863: =IF(B1863="","", A$5)

Sheet 25540045 ชั้นปี 1(B) รุ่น 2569
A1: ระบบทะเบียน | C1: มหาวิทยาลัยเทคโนโลยีพระจอมเกล้าธนบุรี | J1: วันที่พิมพ์ : 25/06/2569
A2: 455024 | C2: รายงานรายชื่อนักศึกษาแยกตามชั้นปี
C3: ภาคการศึกษา : 3/2568
A4: ระดับปริญญาตรี | F4: คณะวิศวกรรมศาสตร์
A5: ภาควิชาวิศวกรรมโยธา | F5: สาขาวิชาวิศวกรรมโยธา
A6: โครงการหลักสูตร 25540045 วิศวกรรมศาสตรบัณฑิต สาขาวิชาวิศวกรรมโยธา ปริญญาตรี 4 ปี
A7: ชั้นปี 1 รุ่นที่เข้าศึกษา 1/2569 ห้อง B อาจารย์ที่ปรึกษา รศ.ดร.วีรชาติ ตั้งจิรภัทร
A8: ลำดับ | B8: รหัสนักศึกษา | D8: ชื่อ-สกุล | H8: อาจารย์ที่ปรึกษาเฉพาะบุคคล
A9: 1 | B9: 69070500648 | D9: นายภาณุวิชญ์ ฤทธิ์บัว | Z9: =IF(B9="","", A$5) -> ภาควิชาวิศวกรรมโยธา
A10: 2 | B10: 69070500649 | D10: นางสาวภารดี รพีศักดิ์ | Z10: =IF(B10="","", A$5) -> ภาควิชาวิศวกรรมโยธา
A11: 3 | B11: 69070500650 | D11: นายภาสวิชญ์ เลิศอาวาส | Z11: =IF(B11="","", A$5) -> ภาควิชาวิศวกรรมโยธา
A12: 4 | B12: 69070500651 | D12: นายภูมัย ดีวงษ์ตระกูล | Z12: =IF(B12="","", A$5) -> ภาควิชาวิศวกรรมโยธา
A13: 5 | B13: 69070500652 | D13: นายโยธิน แคล้วกลาง | Z13: =IF(B13="","", A$5) -> ภาควิชาวิศวกรรมโยธา
A14: 6 | B14: 69070500653 | D14: นางสาวรวงข้าว ดวงวงษา | Z14: =IF(B14="","", A$5) -> ภาควิชาวิศวกรรมโยธา
A15: 7 | B15: 69070500654 | D15: นางสาวรัตนาภรณ์ เศรษฐพิทยากุล | Z15: =IF(B15="","", A$5) -> ภาควิชาวิศวกรรมโยธา
A16: 8 | B16: 69070500655 | D16: นายวรพล เหล่าวิวัฒน์เกษม | Z16: =IF(B16="","", A$5) -> ภาควิชาวิศวกรรมโยธา
A17: 9 | B17: 69070500656 | D17: นายวราเมธ เดชบุญ | Z17: =IF(B17="","", A$5) -> ภาควิชาวิศวกรรมโยธา
A18: 10 | B18: 69070500657 | D18: นายวรายุทธ โพธิ์ชา | Z18: =IF(B18="","", A$5) -> ภาควิชาวิศวกรรมโยธา
A19: 11 | B19: 69070500658 | D19: นายวัชรินทร์ คงตา | Z19: =IF(B19="","", A$5) -> ภาควิชาวิศวกรรมโยธา
A20: 12 | B20: 69070500659 | D20: นางสาววันณภา บุญย่านซื่อ | Z20: =IF(B20="","", A$5) -> ภาควิชาวิศวกรรมโยธา
... A55: 47 | B55: 69070500694 | D55: นายภาสวิชญ์ รอดคง | Z55: =IF(B55="","", A$5) -> ภาควิชาวิศวกรรมโยธา
Z56: =IF(B56="","", A$5)
Z57: =IF(B57="","", A$5)
Z58: =IF(B58="","", A$5)
Z59: =IF(B59="","", A$5)
Z60: =IF(B60="","", A$5)
Z61: =IF(B61="","", A$5)
Z62: =IF(B62="","", A$5)
Z63: =IF(B63="","", A$5)
Z64: =IF(B64="","", A$5)
Z65: =IF(B65="","", A$5)
Z66: =IF(B66="","", A$5)
Z67: =IF(B67="","", A$5)
... Z1863: =IF(B1863="","", A$5)

Sheet 25540046 ชั้นปี 1(A) รุ่น 2569
A1: ระบบทะเบียน | C1: มหาวิทยาลัยเทคโนโลยีพระจอมเกล้าธนบุรี | J1: วันที่พิมพ์ : 25/06/2569
A2: 455024 | C2: รายงานรายชื่อนักศึกษาแยกตามชั้นปี
C3: ภาคการศึกษา : 3/2568
A4: ระดับปริญญาตรี | F4: คณะวิศวกรรมศาสตร์
A5: ภาควิชาวิศวกรรมโยธา | F5: สาขาวิชาวิศวกรรมโยธา
A6: โครงการหลักสูตร 25540046 วิศวกรรมศาสตรบัณฑิต สาขาวิชาวิศวกรรมโยธา ปริญญาตรี 4 ปี (หลักสูตรนานาชาติ)
A7: ชั้นปี 1 รุ่นที่เข้าศึกษา 1/2569 ห้อง A อาจารย์ที่ปรึกษา Asst.Prof.Dr.Goran Arangjelovski
A8: ลำดับ | B8: รหัสนักศึกษา | D8: ชื่อ-สกุล | H8: อาจารย์ที่ปรึกษาเฉพาะบุคคล
A9: 1 | B9: 69070503201 | D9: MR.AUNG PHONE CHEIN | Z9: =IF(B9="","", A$5) -> ภาควิชาวิศวกรรมโยธา
A10: 2 | B10: 69070503202 | D10: MR.HEIN THU | Z10: =IF(B10="","", A$5) -> ภาควิชาวิศวกรรมโยธา
A11: 3 | B11: 69070503203 | D11: MS.MAY MIE MYO THANT | Z11: =IF(B11="","", A$5) -> ภาควิชาวิศวกรรมโยธา
A12: 4 | B12: 69070503204 | D12: MS.SHWE SIN LIN | Z12: =IF(B12="","", A$5) -> ภาควิชาวิศวกรรมโยธา
A13: 5 | B13: 69070503205 | D13: MR.SWAM SAUNG ZAW | Z13: =IF(B13="","", A$5) -> ภาควิชาวิศวกรรมโยธา
A14: 6 | B14: 69070503206 | D14: MS.THAMUDAYA TUN | Z14: =IF(B14="","", A$5) -> ภาควิชาวิศวกรรมโยธา
A15: 7 | B15: 69070503207 | D15: MS.ZUNISBAWITHA CHIN | Z15: =IF(B15="","", A$5) -> ภาควิชาวิศวกรรมโยธา
A16: 8 | B16: 69070503208 | D16: MR.ZWE PAING THU | Z16: =IF(B16="","", A$5) -> ภาควิชาวิศวกรรมโยธา
A17: 9 | B17: 69070503209 | D17: นายกฤตภาส นพวรรณพร | Z17: =IF(B17="","", A$5) -> ภาควิชาวิศวกรรมโยธา
A18: 10 | B18: 69070503210 | D18: นายกลวัชร วิริยนุกูลทรัพย์ | Z18: =IF(B18="","", A$5) -> ภาควิชาวิศวกรรมโยธา
A19: 11 | B19: 69070503211 | D19: นายคุณปราบ กรุณานนท์ | Z19: =IF(B19="","", A$5) -> ภาควิชาวิศวกรรมโยธา
A20: 12 | B20: 69070503212 | D20: นางสาวจิตรวรรณ แก้วกำแหง | Z20: =IF(B20="","", A$5) -> ภาควิชาวิศวกรรมโยธา
... A50: 42 | B50: 69070503242 | D50: MR.BHONE MYAT | Z50: =IF(B50="","", A$5) -> ภาควิชาวิศวกรรมโยธา
Z51: =IF(B51="","", A$5)
Z52: =IF(B52="","", A$5)
Z53: =IF(B53="","", A$5)
Z54: =IF(B54="","", A$5)
Z55: =IF(B55="","", A$5)
Z56: =IF(B56="","", A$5)
Z57: =IF(B57="","", A$5)
Z58: =IF(B58="","", A$5)
Z59: =IF(B59="","", A$5)
Z60: =IF(B60="","", A$5)
Z61: =IF(B61="","", A$5)
Z62: =IF(B62="","", A$5)
... Z1863: =IF(B1863="","", A$5)

Sheet 25540046 ชั้นปี 1(B) รุ่น 2569
A1: ระบบทะเบียน | C1: มหาวิทยาลัยเทคโนโลยีพระจอมเกล้าธนบุรี | J1: วันที่พิมพ์ : 25/06/2569
A2: 455024 | C2: รายงานรายชื่อนักศึกษาแยกตามชั้นปี
C3: ภาคการศึกษา : 3/2568
A4: ระดับปริญญาตรี | F4: คณะวิศวกรรมศาสตร์
A5: ภาควิชาวิศวกรรมโยธา | F5: สาขาวิชาวิศวกรรมโยธา
A6: โครงการหลักสูตร 25540046 วิศวกรรมศาสตรบัณฑิต สาขาวิชาวิศวกรรมโยธา ปริญญาตรี 4 ปี (หลักสูตรนานาชาติ)
A7: ชั้นปี 1 รุ่นที่เข้าศึกษา 1/2569 ห้อง B อาจารย์ที่ปรึกษา Dr.Chamroeun Se
A8: ลำดับ | B8: รหัสนักศึกษา | D8: ชื่อ-สกุล | H8: อาจารย์ที่ปรึกษาเฉพาะบุคคล
A9: 1 | B9: 69070503243 | D9: MR.EIKOE SAN | Z9: =IF(B9="","", A$5) -> ภาควิชาวิศวกรรมโยธา
A10: 2 | B10: 69070503244 | D10: MR.HAN LINN KHANT | Z10: =IF(B10="","", A$5) -> ภาควิชาวิศวกรรมโยธา
A11: 3 | B11: 69070503245 | D11: MR.MOE WIN TUN | Z11: =IF(B11="","", A$5) -> ภาควิชาวิศวกรรมโยธา
A12: 4 | B12: 69070503246 | D12: MR.PYAE PHYO MAUNG | Z12: =IF(B12="","", A$5) -> ภาควิชาวิศวกรรมโยธา
A13: 5 | B13: 69070503247 | D13: MR.SANN THIT HNIT OO | Z13: =IF(B13="","", A$5) -> ภาควิชาวิศวกรรมโยธา
A14: 6 | B14: 69070503248 | D14: MS.SUMYATNOE OO | Z14: =IF(B14="","", A$5) -> ภาควิชาวิศวกรรมโยธา
A15: 7 | B15: 69070503249 | D15: MS.THET HTAR SAN | Z15: =IF(B15="","", A$5) -> ภาควิชาวิศวกรรมโยธา
A16: 8 | B16: 69070503250 | D16: MR.YEE WAI AUNG | Z16: =IF(B16="","", A$5) -> ภาควิชาวิศวกรรมโยธา
A17: 9 | B17: 69070503251 | D17: MR.YE HTUT KHAUNG | Z17: =IF(B17="","", A$5) -> ภาควิชาวิศวกรรมโยธา
A18: 10 | B18: 69070503252 | D18: นายกรณ์ดนัย คำภาอินทร์ | Z18: =IF(B18="","", A$5) -> ภาควิชาวิศวกรรมโยธา
A19: 11 | B19: 69070503253 | D19: นายจิรายุ รอดปราณี | Z19: =IF(B19="","", A$5) -> ภาควิชาวิศวกรรมโยธา
A20: 12 | B20: 69070503254 | D20: นายชิษณุพงศ์ ขนาดนิด | Z20: =IF(B20="","", A$5) -> ภาควิชาวิศวกรรมโยธา
... A50: 42 | B50: 69070503284 | D50: นายอภิสิทธิ์ สัญญะเขื่อน | Z50: =IF(B50="","", A$5) -> ภาควิชาวิศวกรรมโยธา
Z51: =IF(B51="","", A$5)
Z52: =IF(B52="","", A$5)
Z53: =IF(B53="","", A$5)
Z54: =IF(B54="","", A$5)
Z55: =IF(B55="","", A$5)
Z56: =IF(B56="","", A$5)
Z57: =IF(B57="","", A$5)
Z58: =IF(B58="","", A$5)
Z59: =IF(B59="","", A$5)
Z60: =IF(B60="","", A$5)
Z61: =IF(B61="","", A$5)
Z62: =IF(B62="","", A$5)
... Z1863: =IF(B1863="","", A$5)

Sheet 25540062 ชั้นปี 1(A) รุ่น 2569
A1: ระบบทะเบียน | C1: มหาวิทยาลัยเทคโนโลยีพระจอมเกล้าธนบุรี | J1: วันที่พิมพ์ : 25/06/2569
A2: 455024 | C2: รายงานรายชื่อนักศึกษาแยกตามชั้นปี
C3: ภาคการศึกษา : 3/2568
A4: ระดับปริญญาตรี | F4: คณะวิศวกรรมศาสตร์
A5: ภาควิชาวิศวกรรมอุตสาหการ | F5: สาขาวิชาวิศวกรรมอุตสาหการ
A6: โครงการหลักสูตร 25540062 วิศวกรรมศาสตรบัณฑิต สาขาวิชาวิศวกรรมอุตสาหการ ปริญญาตรี 4 ปี
A7: ชั้นปี 1 รุ่นที่เข้าศึกษา 1/2569 ห้อง A อาจารย์ที่ปรึกษา ดร.ก้องเกียรติ ปุภรัตนพงษ์
A8: ลำดับ | B8: รหัสนักศึกษา | D8: ชื่อ-สกุล | H8: อาจารย์ที่ปรึกษาเฉพาะบุคคล
A9: 1 | B9: 69070500801 | D9: นางสาวกนกกานต์ หมื่นศรี | Z9: =IF(B9="","", A$5) -> ภาควิชาวิศวกรรมอุตสาหการ
A10: 2 | B10: 69070500802 | D10: นางสาวกนกพร เดชผล | Z10: =IF(B10="","", A$5) -> ภาควิชาวิศวกรรมอุตสาหการ
A11: 3 | B11: 69070500803 | D11: นางสาวกรชนก แย้มงามเหลือ | Z11: =IF(B11="","", A$5) -> ภาควิชาวิศวกรรมอุตสาหการ
A12: 4 | B12: 69070500804 | D12: นายกรณ์ดนัย กิจนุกูล | Z12: =IF(B12="","", A$5) -> ภาควิชาวิศวกรรมอุตสาหการ
A13: 5 | B13: 69070500805 | D13: นางสาวกัญญาณัฐ เหลือสูงเนิน | Z13: =IF(B13="","", A$5) -> ภาควิชาวิศวกรรมอุตสาหการ
A14: 6 | B14: 69070500806 | D14: นางสาวกัลยา เวียงคำ | Z14: =IF(B14="","", A$5) -> ภาควิชาวิศวกรรมอุตสาหการ
A15: 7 | B15: 69070500807 | D15: นางสาวคีตภัทร เทพจันทร์ | Z15: =IF(B15="","", A$5) -> ภาควิชาวิศวกรรมอุตสาหการ
A16: 8 | B16: 69070500808 | D16: นายเฉกชนก ทับยัง | Z16: =IF(B16="","", A$5) -> ภาควิชาวิศวกรรมอุตสาหการ
A17: 9 | B17: 69070500809 | D17: นางสาวชรินทร์รัตน์ พวงอก | Z17: =IF(B17="","", A$5) -> ภาควิชาวิศวกรรมอุตสาหการ
A18: 10 | B18: 69070500810 | D18: นายณัชพล สุขพล | Z18: =IF(B18="","", A$5) -> ภาควิชาวิศวกรรมอุตสาหการ
A19: 11 | B19: 69070500811 | D19: นางสาวณัฐณิชา ตั้งจินตวิวัฒน์ | Z19: =IF(B19="","", A$5) -> ภาควิชาวิศวกรรมอุตสาหการ
A20: 12 | B20: 69070500812 | D20: นายณัฐวัศ แสงทอง | Z20: =IF(B20="","", A$5) -> ภาควิชาวิศวกรรมอุตสาหการ
... A51: 43 | B51: 69070500843 | D51: นางสาวญาณิศา นิตยะ | Z51: =IF(B51="","", A$5) -> ภาควิชาวิศวกรรมอุตสาหการ
Z52: =IF(B52="","", A$5)
Z53: =IF(B53="","", A$5)
Z54: =IF(B54="","", A$5)
Z55: =IF(B55="","", A$5)
Z56: =IF(B56="","", A$5)
Z57: =IF(B57="","", A$5)
Z58: =IF(B58="","", A$5)
Z59: =IF(B59="","", A$5)
Z60: =IF(B60="","", A$5)
Z61: =IF(B61="","", A$5)
Z62: =IF(B62="","", A$5)
Z63: =IF(B63="","", A$5)
... Z1863: =IF(B1863="","", A$5)

Sheet 25540062 ชั้นปี 1(B) รุ่น 2569
A1: ระบบทะเบียน | C1: มหาวิทยาลัยเทคโนโลยีพระจอมเกล้าธนบุรี | J1: วันที่พิมพ์ : 25/06/2569
A2: 455024 | C2: รายงานรายชื่อนักศึกษาแยกตามชั้นปี
C3: ภาคการศึกษา : 3/2568
A4: ระดับปริญญาตรี | F4: คณะวิศวกรรมศาสตร์
A5: ภาควิชาวิศวกรรมอุตสาหการ | F5: สาขาวิชาวิศวกรรมอุตสาหการ
A6: โครงการหลักสูตร 25540062 วิศวกรรมศาสตรบัณฑิต สาขาวิชาวิศวกรรมอุตสาหการ ปริญญาตรี 4 ปี
A7: ชั้นปี 1 รุ่นที่เข้าศึกษา 1/2569 ห้อง B อาจารย์ที่ปรึกษา ดร.ศุภฤกษ์ บุญเทียร
A8: ลำดับ | B8: รหัสนักศึกษา | D8: ชื่อ-สกุล | H8: อาจารย์ที่ปรึกษาเฉพาะบุคคล
A9: 1 | B9: 69070500844 | D9: นายณัฐฐากร เวียงอินทร์ | Z9: =IF(B9="","", A$5) -> ภาควิชาวิศวกรรมอุตสาหการ
A10: 2 | B10: 69070500845 | D10: นางสาวณัฐนิชา คงสัง | Z10: =IF(B10="","", A$5) -> ภาควิชาวิศวกรรมอุตสาหการ
A11: 3 | B11: 69070500846 | D11: นายเดชสิทธิ์ กระจ่างโพธิ์ | Z11: =IF(B11="","", A$5) -> ภาควิชาวิศวกรรมอุตสาหการ
A12: 4 | B12: 69070500847 | D12: นายเทิศวรุฒม์ เกียรติสมบูรณ์ชัย | Z12: =IF(B12="","", A$5) -> ภาควิชาวิศวกรรมอุตสาหการ
A13: 5 | B13: 69070500848 | D13: นายแทนคุณ พ่วงเผือก | Z13: =IF(B13="","", A$5) -> ภาควิชาวิศวกรรมอุตสาหการ
A14: 6 | B14: 69070500849 | D14: นายธนพัต ไตรยะถา | Z14: =IF(B14="","", A$5) -> ภาควิชาวิศวกรรมอุตสาหการ
A15: 7 | B15: 69070500850 | D15: นายธนัช เก้าเอี้ยน | Z15: =IF(B15="","", A$5) -> ภาควิชาวิศวกรรมอุตสาหการ
A16: 8 | B16: 69070500851 | D16: นางสาวธัญชนก ทองกันยา | Z16: =IF(B16="","", A$5) -> ภาควิชาวิศวกรรมอุตสาหการ
A17: 9 | B17: 69070500852 | D17: นางสาวธัญสิริ ธีรภัศกุล | Z17: =IF(B17="","", A$5) -> ภาควิชาวิศวกรรมอุตสาหการ
A18: 10 | B18: 69070500853 | D18: นางสาวนริศรา ยากอง | Z18: =IF(B18="","", A$5) -> ภาควิชาวิศวกรรมอุตสาหการ
A19: 11 | B19: 69070500854 | D19: นางสาวนัทธ์วรินทร์ มั่นศิลป์ | Z19: =IF(B19="","", A$5) -> ภาควิชาวิศวกรรมอุตสาหการ
A20: 12 | B20: 69070500855 | D20: นายนัทวิช สุขอ่ำ | Z20: =IF(B20="","", A$5) -> ภาควิชาวิศวกรรมอุตสาหการ
... A51: 43 | B51: 69070500886 | D51: นายเศรษฐกรณ์ อุ่นโพธิ์ | Z51: =IF(B51="","", A$5) -> ภาควิชาวิศวกรรมอุตสาหการ
Z52: =IF(B52="","", A$5)
Z53: =IF(B53="","", A$5)
Z54: =IF(B54="","", A$5)
Z55: =IF(B55="","", A$5)
Z56: =IF(B56="","", A$5)
Z57: =IF(B57="","", A$5)
Z58: =IF(B58="","", A$5)
Z59: =IF(B59="","", A$5)
Z60: =IF(B60="","", A$5)
Z61: =IF(B61="","", A$5)
Z62: =IF(B62="","", A$5)
Z63: =IF(B63="","", A$5)
... Z1863: =IF(B1863="","", A$5)

Sheet 25540081 ชั้นปี 1(A) รุ่น 2569
A1: ระบบทะเบียน | C1: มหาวิทยาลัยเทคโนโลยีพระจอมเกล้าธนบุรี | J1: วันที่พิมพ์ : 25/06/2569
A2: 455024 | C2: รายงานรายชื่อนักศึกษาแยกตามชั้นปี
C3: ภาคการศึกษา : 3/2568
A4: ระดับปริญญาตรี | F4: คณะวิศวกรรมศาสตร์
A5: ภาควิชาวิศวกรรมอุตสาหการ | F5: สาขาวิชาวิศวกรรมเมคคาทรอนิกส์
A6: โครงการหลักสูตร 25540081 วิศวกรรมศาสตรบัณฑิต สาขาวิชาวิศวกรรมเมคคาทรอนิกส์ ปริญญาตรี 4 ปี
A7: ชั้นปี 1 รุ่นที่เข้าศึกษา 1/2569 ห้อง A อาจารย์ที่ปรึกษา ดร.พิเนษฐ์ ศรีโยธา
A8: ลำดับ | B8: รหัสนักศึกษา | D8: ชื่อ-สกุล | H8: อาจารย์ที่ปรึกษาเฉพาะบุคคล
A9: 1 | B9: 69070502201 | D9: นายกฤษณ์กวิน วิญญาสุข | Z9: =IF(B9="","", A$5) -> ภาควิชาวิศวกรรมอุตสาหการ
A10: 2 | B10: 69070502202 | D10: นายก้องภพ พรหมมี | Z10: =IF(B10="","", A$5) -> ภาควิชาวิศวกรรมอุตสาหการ
A11: 3 | B11: 69070502203 | D11: นางสาวจิรภิญญา คำทอง | Z11: =IF(B11="","", A$5) -> ภาควิชาวิศวกรรมอุตสาหการ
A12: 4 | B12: 69070502204 | D12: นายชนานนท์ นาคสมบูรณ์ชัย | Z12: =IF(B12="","", A$5) -> ภาควิชาวิศวกรรมอุตสาหการ
A13: 5 | B13: 69070502205 | D13: นางสาวณัฐจิรา แสงโชติ | Z13: =IF(B13="","", A$5) -> ภาควิชาวิศวกรรมอุตสาหการ
A14: 6 | B14: 69070502206 | D14: นายณัฐชนน นิรันดรรัตน์ | Z14: =IF(B14="","", A$5) -> ภาควิชาวิศวกรรมอุตสาหการ
A15: 7 | B15: 69070502207 | D15: นายณัฐนันท์ อุประ | Z15: =IF(B15="","", A$5) -> ภาควิชาวิศวกรรมอุตสาหการ
A16: 8 | B16: 69070502209 | D16: นายตฤณ เหล่าเทพาวัฒน์ | Z16: =IF(B16="","", A$5) -> ภาควิชาวิศวกรรมอุตสาหการ
A17: 9 | B17: 69070502210 | D17: นายธรรมโชติ วิสิฐศักดิ์ชัย | Z17: =IF(B17="","", A$5) -> ภาควิชาวิศวกรรมอุตสาหการ
A18: 10 | B18: 69070502211 | D18: นายธีรเดช บุญบำรุงชัย | Z18: =IF(B18="","", A$5) -> ภาควิชาวิศวกรรมอุตสาหการ
A19: 11 | B19: 69070502212 | D19: นายนนทพัทธ์ โลณวัณต์ | Z19: =IF(B19="","", A$5) -> ภาควิชาวิศวกรรมอุตสาหการ
A20: 12 | B20: 69070502213 | D20: นายนนทวัชร์ ม่วงพัฒน์ | Z20: =IF(B20="","", A$5) -> ภาควิชาวิศวกรรมอุตสาหการ
... A52: 44 | B52: 69070502245 | D52: นายอาทิตย์ ชัยบุญญลักษณ์ | Z52: =IF(B52="","", A$5) -> ภาควิชาวิศวกรรมอุตสาหการ
Z53: =IF(B53="","", A$5)
Z54: =IF(B54="","", A$5)
Z55: =IF(B55="","", A$5)
Z56: =IF(B56="","", A$5)
Z57: =IF(B57="","", A$5)
Z58: =IF(B58="","", A$5)
Z59: =IF(B59="","", A$5)
Z60: =IF(B60="","", A$5)
Z61: =IF(B61="","", A$5)
Z62: =IF(B62="","", A$5)
Z63: =IF(B63="","", A$5)
Z64: =IF(B64="","", A$5)
... Z1863: =IF(B1863="","", A$5)

Sheet 25540098 ชั้นปี 1(A) รุ่น 2569
A1: ระบบทะเบียน | C1: มหาวิทยาลัยเทคโนโลยีพระจอมเกล้าธนบุรี | J1: วันที่พิมพ์ : 25/06/2569
A2: 455024 | C2: รายงานรายชื่อนักศึกษาแยกตามชั้นปี
C3: ภาคการศึกษา : 3/2568
A4: ระดับปริญญาตรี | F4: คณะวิศวกรรมศาสตร์
A5: ภาควิชาวิศวกรรมคอมพิวเตอร์ | F5: สาขาวิชาวิศวกรรมคอมพิวเตอร์
A6: โครงการหลักสูตร 25540098 วิศวกรรมศาสตรบัณฑิต สาขาวิชาวิศวกรรมคอมพิวเตอร์ ปริญญาตรี 4 ปี
A7: ชั้นปี 1 รุ่นที่เข้าศึกษา 1/2569 ห้อง A อาจารย์ที่ปรึกษา ผศ.ดร.ปริยกร ปุสวิโร, รศ.ดร.พีรพล ศิริพงศ์วุฒิกร
A8: ลำดับ | B8: รหัสนักศึกษา | D8: ชื่อ-สกุล | H8: อาจารย์ที่ปรึกษาเฉพาะบุคคล
A9: 1 | B9: 69070501001 | D9: นางสาวกนกรดา แซ่เฮง | Z9: =IF(B9="","", A$5) -> ภาควิชาวิศวกรรมคอมพิวเตอร์
A10: 2 | B10: 69070501002 | D10: นายกฤตพล นามบุตร | Z10: =IF(B10="","", A$5) -> ภาควิชาวิศวกรรมคอมพิวเตอร์
A11: 3 | B11: 69070501003 | D11: นายกษิดิ์พิชญ์คุณ ชัยกุลเสรีวัฒน์ | Z11: =IF(B11="","", A$5) -> ภาควิชาวิศวกรรมคอมพิวเตอร์
A12: 4 | B12: 69070501004 | D12: นางสาวเขมณัฎฐ์ เขียวสนั่น | Z12: =IF(B12="","", A$5) -> ภาควิชาวิศวกรรมคอมพิวเตอร์
A13: 5 | B13: 69070501005 | D13: นายคุณาธิป กิติโสภากูล | Z13: =IF(B13="","", A$5) -> ภาควิชาวิศวกรรมคอมพิวเตอร์
A14: 6 | B14: 69070501006 | D14: นายเจษฎาวุฒิ แสงสุวรรณ์ | Z14: =IF(B14="","", A$5) -> ภาควิชาวิศวกรรมคอมพิวเตอร์
A15: 7 | B15: 69070501007 | D15: นางสาวชญาภา ประภาพันธ์ | Z15: =IF(B15="","", A$5) -> ภาควิชาวิศวกรรมคอมพิวเตอร์
A16: 8 | B16: 69070501008 | D16: นางสาวชนิศา นิยม | Z16: =IF(B16="","", A$5) -> ภาควิชาวิศวกรรมคอมพิวเตอร์
A17: 9 | B17: 69070501009 | D17: นางสาวชลชญา สินใช้ | Z17: =IF(B17="","", A$5) -> ภาควิชาวิศวกรรมคอมพิวเตอร์
A18: 10 | B18: 69070501010 | D18: นายชลิตตาณ จันทรสวัสดิ์ | Z18: =IF(B18="","", A$5) -> ภาควิชาวิศวกรรมคอมพิวเตอร์
A19: 11 | B19: 69070501011 | D19: นายชวนากร รอดพาที | Z19: =IF(B19="","", A$5) -> ภาควิชาวิศวกรรมคอมพิวเตอร์
A20: 12 | B20: 69070501012 | D20: นายชิตประจักษ์ สวัสดิโสภา | Z20: =IF(B20="","", A$5) -> ภาควิชาวิศวกรรมคอมพิวเตอร์
... A48: 40 | B48: 69070501041 | D48: นายเศรษฐ์ศรุต กตคุณไพศาล | Z48: =IF(B48="","", A$5) -> ภาควิชาวิศวกรรมคอมพิวเตอร์
Z49: =IF(B49="","", A$5)
Z50: =IF(B50="","", A$5)
Z51: =IF(B51="","", A$5)
Z52: =IF(B52="","", A$5)
Z53: =IF(B53="","", A$5)
Z54: =IF(B54="","", A$5)
Z55: =IF(B55="","", A$5)
Z56: =IF(B56="","", A$5)
Z57: =IF(B57="","", A$5)
Z58: =IF(B58="","", A$5)
Z59: =IF(B59="","", A$5)
Z60: =IF(B60="","", A$5)
... Z1863: =IF(B1863="","", A$5)

Sheet 25540098 ชั้นปี 1(B) รุ่น 2569
A1: ระบบทะเบียน | C1: มหาวิทยาลัยเทคโนโลยีพระจอมเกล้าธนบุรี | J1: วันที่พิมพ์ : 25/06/2569
A2: 455024 | C2: รายงานรายชื่อนักศึกษาแยกตามชั้นปี
C3: ภาคการศึกษา : 3/2568
A4: ระดับปริญญาตรี | F4: คณะวิศวกรรมศาสตร์
A5: ภาควิชาวิศวกรรมคอมพิวเตอร์ | F5: สาขาวิชาวิศวกรรมคอมพิวเตอร์
A6: โครงการหลักสูตร 25540098 วิศวกรรมศาสตรบัณฑิต สาขาวิชาวิศวกรรมคอมพิวเตอร์ ปริญญาตรี 4 ปี
A7: ชั้นปี 1 รุ่นที่เข้าศึกษา 1/2569 ห้อง B อาจารย์ที่ปรึกษา -
A8: ลำดับ | B8: รหัสนักศึกษา | D8: ชื่อ-สกุล | H8: อาจารย์ที่ปรึกษาเฉพาะบุคคล
A9: 1 | B9: 69070501042 | D9: นายสิทธินนท์ ขระเขื่อน | Z9: =IF(B9="","", A$5) -> ภาควิชาวิศวกรรมคอมพิวเตอร์
A10: 2 | B10: 69070501043 | D10: นางสาวสุชานาถ เรืองกัณฑ์ | Z10: =IF(B10="","", A$5) -> ภาควิชาวิศวกรรมคอมพิวเตอร์
A11: 3 | B11: 69070501044 | D11: นายอรรถชาต ชาญเชาว์วงศ์ | Z11: =IF(B11="","", A$5) -> ภาควิชาวิศวกรรมคอมพิวเตอร์
A12: 4 | B12: 69070501045 | D12: นายอิบรอเหม อุสมา | Z12: =IF(B12="","", A$5) -> ภาควิชาวิศวกรรมคอมพิวเตอร์
A13: 5 | B13: 69070501046 | D13: นางสาวอุ่นรัก หนูสุรา | Z13: =IF(B13="","", A$5) -> ภาควิชาวิศวกรรมคอมพิวเตอร์
A14: 6 | B14: 69070501047 | D14: นางสาวไอดิน ศรีสะอาด | Z14: =IF(B14="","", A$5) -> ภาควิชาวิศวกรรมคอมพิวเตอร์
A15: 7 | B15: 69070501048 | D15: นายกฤตกร พรเดชวงศ์ | Z15: =IF(B15="","", A$5) -> ภาควิชาวิศวกรรมคอมพิวเตอร์
A16: 8 | B16: 69070501049 | D16: นายกฤษฏิปุณ หุ้นเอียด | Z16: =IF(B16="","", A$5) -> ภาควิชาวิศวกรรมคอมพิวเตอร์
A17: 9 | B17: 69070501050 | D17: นางสาวณัฐชยา เจียรพิพัฒน์พงศ์ | Z17: =IF(B17="","", A$5) -> ภาควิชาวิศวกรรมคอมพิวเตอร์
A18: 10 | B18: 69070501051 | D18: นายธนโชค ดอกไม้ทอง | Z18: =IF(B18="","", A$5) -> ภาควิชาวิศวกรรมคอมพิวเตอร์
A19: 11 | B19: 69070501052 | D19: นายธารณ์ ตริ่งวัน | Z19: =IF(B19="","", A$5) -> ภาควิชาวิศวกรรมคอมพิวเตอร์
A20: 12 | B20: 69070501053 | D20: นายนราวิชญ์ แดงประวัติ | Z20: =IF(B20="","", A$5) -> ภาควิชาวิศวกรรมคอมพิวเตอร์
... A48: 40 | B48: 69070501081 | D48: นายหาญณรงค์ ปังคะดารา | Z48: =IF(B48="","", A$5) -> ภาควิชาวิศวกรรมคอมพิวเตอร์
Z49: =IF(B49="","", A$5)
Z50: =IF(B50="","", A$5)
Z51: =IF(B51="","", A$5)
Z52: =IF(B52="","", A$5)
Z53: =IF(B53="","", A$5)
Z54: =IF(B54="","", A$5)
Z55: =IF(B55="","", A$5)
Z56: =IF(B56="","", A$5)
Z57: =IF(B57="","", A$5)
Z58: =IF(B58="","", A$5)
Z59: =IF(B59="","", A$5)
Z60: =IF(B60="","", A$5)
... Z1863: =IF(B1863="","", A$5)

Sheet 25540099 ชั้นปี 1(A) รุ่น 2569
A1: ระบบทะเบียน | C1: มหาวิทยาลัยเทคโนโลยีพระจอมเกล้าธนบุรี | J1: วันที่พิมพ์ : 25/06/2569
A2: 455024 | C2: รายงานรายชื่อนักศึกษาแยกตามชั้นปี
C3: ภาคการศึกษา : 3/2568
A4: ระดับปริญญาตรี | F4: คณะวิศวกรรมศาสตร์
A5: ภาควิชาวิศวกรรมคอมพิวเตอร์ | F5: สาขาวิชาวิศวกรรมคอมพิวเตอร์
A6: โครงการหลักสูตร 25540099 วิศวกรรมศาสตรบัณฑิต สาขาวิชาวิศวกรรมคอมพิวเตอร์ ปริญญาตรี 4 ปี (หลักสูตรนานาชาติ)
A7: ชั้นปี 1 รุ่นที่เข้าศึกษา 1/2569 ห้อง A อาจารย์ที่ปรึกษา รศ.ดร.ณัฐชา เดชดำรง, Dr.Aung Myo Htut
A8: ลำดับ | B8: รหัสนักศึกษา | D8: ชื่อ-สกุล | H8: อาจารย์ที่ปรึกษาเฉพาะบุคคล
A9: 1 | B9: 69070503401 | D9: MR.KHANT NYAR KO | Z9: =IF(B9="","", A$5) -> ภาควิชาวิศวกรรมคอมพิวเตอร์
A10: 2 | B10: 69070503402 | D10: MS.MAY THU THU KHAING | Z10: =IF(B10="","", A$5) -> ภาควิชาวิศวกรรมคอมพิวเตอร์
A11: 3 | B11: 69070503403 | D11: MR.NYAN LIN HTET | Z11: =IF(B11="","", A$5) -> ภาควิชาวิศวกรรมคอมพิวเตอร์
A12: 4 | B12: 69070503404 | D12: MR.YUCHENG ZHU | Z12: =IF(B12="","", A$5) -> ภาควิชาวิศวกรรมคอมพิวเตอร์
A13: 5 | B13: 69070503405 | D13: นางสาวกรกนก ธรรมกมล | Z13: =IF(B13="","", A$5) -> ภาควิชาวิศวกรรมคอมพิวเตอร์
A14: 6 | B14: 69070503406 | D14: นายกฤชณัท อุดมวัจนศักดิ์ | Z14: =IF(B14="","", A$5) -> ภาควิชาวิศวกรรมคอมพิวเตอร์
A15: 7 | B15: 69070503407 | D15: นายกฤตภาส ธนาผลไพบูลย์ | Z15: =IF(B15="","", A$5) -> ภาควิชาวิศวกรรมคอมพิวเตอร์
A16: 8 | B16: 69070503408 | D16: นายกิตติรัตน์ วิชชุประสิทธิกร | Z16: =IF(B16="","", A$5) -> ภาควิชาวิศวกรรมคอมพิวเตอร์
A17: 9 | B17: 69070503409 | D17: นายกิตติศักดิ์ ศิริวงศ์ | Z17: =IF(B17="","", A$5) -> ภาควิชาวิศวกรรมคอมพิวเตอร์
A18: 10 | B18: 69070503410 | D18: นางสาวกุลชญารัชย์ อนุประเสริฐ | Z18: =IF(B18="","", A$5) -> ภาควิชาวิศวกรรมคอมพิวเตอร์
A19: 11 | B19: 69070503411 | D19: นายจิระณัฐ ณัฐปติรุ่งโรจน์ | Z19: =IF(B19="","", A$5) -> ภาควิชาวิศวกรรมคอมพิวเตอร์
A20: 12 | B20: 69070503412 | D20: นายชนวีร์ พิมพ์โปร่ง | Z20: =IF(B20="","", A$5) -> ภาควิชาวิศวกรรมคอมพิวเตอร์
... A53: 45 | B53: 69070503446 | D53: นายศิรณัฏฐ์ พุทธชัย | Z53: =IF(B53="","", A$5) -> ภาควิชาวิศวกรรมคอมพิวเตอร์
Z54: =IF(B54="","", A$5)
Z55: =IF(B55="","", A$5)
Z56: =IF(B56="","", A$5)
Z57: =IF(B57="","", A$5)
Z58: =IF(B58="","", A$5)
Z59: =IF(B59="","", A$5)
Z60: =IF(B60="","", A$5)
Z61: =IF(B61="","", A$5)
Z62: =IF(B62="","", A$5)
Z63: =IF(B63="","", A$5)
Z64: =IF(B64="","", A$5)
Z65: =IF(B65="","", A$5)
... Z1863: =IF(B1863="","", A$5)

Sheet 25540099 ชั้นปี 1(B) รุ่น 2569
A1: ระบบทะเบียน | C1: มหาวิทยาลัยเทคโนโลยีพระจอมเกล้าธนบุรี | J1: วันที่พิมพ์ : 25/06/2569
A2: 455024 | C2: รายงานรายชื่อนักศึกษาแยกตามชั้นปี
C3: ภาคการศึกษา : 3/2568
A4: ระดับปริญญาตรี | F4: คณะวิศวกรรมศาสตร์
A5: ภาควิชาวิศวกรรมคอมพิวเตอร์ | F5: สาขาวิชาวิศวกรรมคอมพิวเตอร์
A6: โครงการหลักสูตร 25540099 วิศวกรรมศาสตรบัณฑิต สาขาวิชาวิศวกรรมคอมพิวเตอร์ ปริญญาตรี 4 ปี (หลักสูตรนานาชาติ)
A7: ชั้นปี 1 รุ่นที่เข้าศึกษา 1/2569 ห้อง B อาจารย์ที่ปรึกษา -
A8: ลำดับ | B8: รหัสนักศึกษา | D8: ชื่อ-สกุล | H8: อาจารย์ที่ปรึกษาเฉพาะบุคคล
A9: 1 | B9: 69070503447 | D9: นายศิวกร วัฒนาเลิศสกุล | Z9: =IF(B9="","", A$5) -> ภาควิชาวิศวกรรมคอมพิวเตอร์
A10: 2 | B10: 69070503448 | D10: นายศุภกร พุ่มไม้ | Z10: =IF(B10="","", A$5) -> ภาควิชาวิศวกรรมคอมพิวเตอร์
A11: 3 | B11: 69070503449 | D11: นายสิรภพ เตชทิพากร | Z11: =IF(B11="","", A$5) -> ภาควิชาวิศวกรรมคอมพิวเตอร์
A12: 4 | B12: 69070503450 | D12: นายอชิระ จิระรัตน์ | Z12: =IF(B12="","", A$5) -> ภาควิชาวิศวกรรมคอมพิวเตอร์
A13: 5 | B13: 69070503451 | D13: นายอธิปพัทธ์ เมฆนันทไพศิฐ | Z13: =IF(B13="","", A$5) -> ภาควิชาวิศวกรรมคอมพิวเตอร์
A14: 6 | B14: 69070503452 | D14: นางสาวอริญชยา ลิมปานุภาพ | Z14: =IF(B14="","", A$5) -> ภาควิชาวิศวกรรมคอมพิวเตอร์
A15: 7 | B15: 69070503453 | D15: นางสาวอริสรา วาณิชอนันต์ชัย | Z15: =IF(B15="","", A$5) -> ภาควิชาวิศวกรรมคอมพิวเตอร์
A16: 8 | B16: 69070503454 | D16: นายอัครวินท์ รุจิปราชญ์ | Z16: =IF(B16="","", A$5) -> ภาควิชาวิศวกรรมคอมพิวเตอร์
A17: 9 | B17: 69070503455 | D17: MS.EI CHELL ZIN YUNN | Z17: =IF(B17="","", A$5) -> ภาควิชาวิศวกรรมคอมพิวเตอร์
A18: 10 | B18: 69070503456 | D18: MR.KHYATIMONTA GOGOI | Z18: =IF(B18="","", A$5) -> ภาควิชาวิศวกรรมคอมพิวเตอร์
A19: 11 | B19: 69070503457 | D19: นางสาวMAY THU ZIN | Z19: =IF(B19="","", A$5) -> ภาควิชาวิศวกรรมคอมพิวเตอร์
A20: 12 | B20: 69070503458 | D20: นายYE WINT KYAW | Z20: =IF(B20="","", A$5) -> ภาควิชาวิศวกรรมคอมพิวเตอร์
... A52: 44 | B52: 69070503490 | D52: นายเหมราอัสดร พลทะกลาง | Z52: =IF(B52="","", A$5) -> ภาควิชาวิศวกรรมคอมพิวเตอร์
Z53: =IF(B53="","", A$5)
Z54: =IF(B54="","", A$5)
Z55: =IF(B55="","", A$5)
Z56: =IF(B56="","", A$5)
Z57: =IF(B57="","", A$5)
Z58: =IF(B58="","", A$5)
Z59: =IF(B59="","", A$5)
Z60: =IF(B60="","", A$5)
Z61: =IF(B61="","", A$5)
Z62: =IF(B62="","", A$5)
Z63: =IF(B63="","", A$5)
Z64: =IF(B64="","", A$5)
... Z1863: =IF(B1863="","", A$5)

Sheet 25540103 ชั้นปี 1(A) รุ่น 2569
A1: ระบบทะเบียน | C1: มหาวิทยาลัยเทคโนโลยีพระจอมเกล้าธนบุรี | J1: วันที่พิมพ์ : 25/06/2569
A2: 455024 | C2: รายงานรายชื่อนักศึกษาแยกตามชั้นปี
C3: ภาคการศึกษา : 3/2568
A4: ระดับปริญญาตรี | F4: คณะวิศวกรรมศาสตร์
A5: ภาควิชาวิศวกรรมระบบควบคุมและเครื่องมือวัด | F5: สาขาวิชาวิศวกรรมระบบควบคุมและเครื่องมือวัด
A6: โครงการหลักสูตร 25540103 วิศวกรรมศาสตรบัณฑิต สาขาวิชาวิศวกรรมระบบควบคุมและเครื่องมือวัด ปริญญาตรี 4 ปี
A7: ชั้นปี 1 รุ่นที่เข้าศึกษา 1/2569 ห้อง A อาจารย์ที่ปรึกษา ดร.เริงรุจ รุจนะไกรกานต์
A8: ลำดับ | B8: รหัสนักศึกษา | D8: ชื่อ-สกุล | H8: อาจารย์ที่ปรึกษาเฉพาะบุคคล
A9: 1 | B9: 69070501201 | D9: นายกรธวัช จิตร์หาญ | Z9: =IF(B9="","", A$5) -> ภาควิชาวิศวกรรมระบบควบคุมและเครื่องมือวัด
A10: 2 | B10: 69070501202 | D10: นายกวินภพ คงเพียรธรรม | Z10: =IF(B10="","", A$5) -> ภาควิชาวิศวกรรมระบบควบคุมและเครื่องมือวัด
A11: 3 | B11: 69070501203 | D11: นายคณาธิป เวลุวรรณใน | Z11: =IF(B11="","", A$5) -> ภาควิชาวิศวกรรมระบบควบคุมและเครื่องมือวัด
A12: 4 | B12: 69070501204 | D12: นายเจตภาณุ มาตายะศรี | Z12: =IF(B12="","", A$5) -> ภาควิชาวิศวกรรมระบบควบคุมและเครื่องมือวัด
A13: 5 | B13: 69070501205 | D13: นายฉัตรอานนท์ ดิลกสิริชาติ | Z13: =IF(B13="","", A$5) -> ภาควิชาวิศวกรรมระบบควบคุมและเครื่องมือวัด
A14: 6 | B14: 69070501206 | D14: นางสาวชนกเนตร การเกษ | Z14: =IF(B14="","", A$5) -> ภาควิชาวิศวกรรมระบบควบคุมและเครื่องมือวัด
A15: 7 | B15: 69070501207 | D15: นายชนัณชัย สัมพันธวงศ์กวี | Z15: =IF(B15="","", A$5) -> ภาควิชาวิศวกรรมระบบควบคุมและเครื่องมือวัด
A16: 8 | B16: 69070501208 | D16: นายชินภัทร ชาติศรี | Z16: =IF(B16="","", A$5) -> ภาควิชาวิศวกรรมระบบควบคุมและเครื่องมือวัด
A17: 9 | B17: 69070501209 | D17: นายชุติมันต์ คงสังข์ | Z17: =IF(B17="","", A$5) -> ภาควิชาวิศวกรรมระบบควบคุมและเครื่องมือวัด
A18: 10 | B18: 69070501210 | D18: นางสาวณัฏฐา นิมมาน | Z18: =IF(B18="","", A$5) -> ภาควิชาวิศวกรรมระบบควบคุมและเครื่องมือวัด
A19: 11 | B19: 69070501211 | D19: นางสาวณัฐชานันท์ กนกวารีรัตน์ | Z19: =IF(B19="","", A$5) -> ภาควิชาวิศวกรรมระบบควบคุมและเครื่องมือวัด
A20: 12 | B20: 69070501212 | D20: นางสาวณัฐริการ์ โฮกสูงเนิน | Z20: =IF(B20="","", A$5) -> ภาควิชาวิศวกรรมระบบควบคุมและเครื่องมือวัด
... A94: 86 | B94: 69070501286 | D94: นายอิทธิพล แซ่ก๊วย | Z94: =IF(B94="","", A$5) -> ภาควิชาวิศวกรรมระบบควบคุมและเครื่องมือวัด
Z95: =IF(B95="","", A$5)
Z96: =IF(B96="","", A$5)
Z97: =IF(B97="","", A$5)
Z98: =IF(B98="","", A$5)
Z99: =IF(B99="","", A$5)
Z100: =IF(B100="","", A$5)
Z101: =IF(B101="","", A$5)
Z102: =IF(B102="","", A$5)
Z103: =IF(B103="","", A$5)
Z104: =IF(B104="","", A$5)
Z105: =IF(B105="","", A$5)
Z106: =IF(B106="","", A$5)
... Z1863: =IF(B1863="","", A$5)

Sheet 25540128 ชั้นปี 1(A) รุ่น 2569
A1: ระบบทะเบียน | C1: มหาวิทยาลัยเทคโนโลยีพระจอมเกล้าธนบุรี | J1: วันที่พิมพ์ : 25/06/2569
A2: 455024 | C2: รายงานรายชื่อนักศึกษาแยกตามชั้นปี
C3: ภาคการศึกษา : 3/2568
A4: ระดับปริญญาตรี | F4: คณะวิศวกรรมศาสตร์
A5: ภาควิชาวิศวกรรมอิเล็กทรอนิกส์และโทรคมนาคม | F5: สาขาวิชาวิศวกรรมไฟฟ้าสื่อสารและอิเล็กทรอนิกส์
A6: โครงการหลักสูตร 25540128 วิศวกรรมศาสตรบัณฑิต สาขาวิชาวิศวกรรมไฟฟ้าสื่อสารและอิเล็กทรอนิกส์ ปริญญาตรี 4 ปี
A7: ชั้นปี 1 รุ่นที่เข้าศึกษา 1/2569 ห้อง A อาจารย์ที่ปรึกษา อ.เอื้อพงศ์ ใยเจริญ
A8: ลำดับ | B8: รหัสนักศึกษา | D8: ชื่อ-สกุล | H8: อาจารย์ที่ปรึกษาเฉพาะบุคคล
A9: 1 | B9: 69070502401 | D9: นายกฤตภัค สุกใส | Z9: =IF(B9="","", A$5) -> ภาควิชาวิศวกรรมอิเล็กทรอนิกส์และโทรคมนาคม
A10: 2 | B10: 69070502402 | D10: นางสาวกัญจน์ชญา เตียนโพธิ์ทอง | Z10: =IF(B10="","", A$5) -> ภาควิชาวิศวกรรมอิเล็กทรอนิกส์และโทรคมนาคม
A11: 3 | B11: 69070502403 | D11: นายกิตตินันท์ ไฉนวงศ์ | Z11: =IF(B11="","", A$5) -> ภาควิชาวิศวกรรมอิเล็กทรอนิกส์และโทรคมนาคม
A12: 4 | B12: 69070502404 | D12: นายกิตติภัทร คำมณี | Z12: =IF(B12="","", A$5) -> ภาควิชาวิศวกรรมอิเล็กทรอนิกส์และโทรคมนาคม
A13: 5 | B13: 69070502405 | D13: นางสาวเกวลิน นาชัย | Z13: =IF(B13="","", A$5) -> ภาควิชาวิศวกรรมอิเล็กทรอนิกส์และโทรคมนาคม
A14: 6 | B14: 69070502406 | D14: นายเกียรติกุล ฮะยู้ | Z14: =IF(B14="","", A$5) -> ภาควิชาวิศวกรรมอิเล็กทรอนิกส์และโทรคมนาคม
A15: 7 | B15: 69070502407 | D15: นายเกียรติศิริ ตันพันตรี | Z15: =IF(B15="","", A$5) -> ภาควิชาวิศวกรรมอิเล็กทรอนิกส์และโทรคมนาคม
A16: 8 | B16: 69070502408 | D16: นายคมกริช ฉิมพลี | Z16: =IF(B16="","", A$5) -> ภาควิชาวิศวกรรมอิเล็กทรอนิกส์และโทรคมนาคม
A17: 9 | B17: 69070502409 | D17: นางสาวจิราภา สุขผดุง | Z17: =IF(B17="","", A$5) -> ภาควิชาวิศวกรรมอิเล็กทรอนิกส์และโทรคมนาคม
A18: 10 | B18: 69070502410 | D18: นายเจตพิพัฒน์ พงษ์สีมา | Z18: =IF(B18="","", A$5) -> ภาควิชาวิศวกรรมอิเล็กทรอนิกส์และโทรคมนาคม
A19: 11 | B19: 69070502411 | D19: นายเจษฎากร ไชยมาตร์ | Z19: =IF(B19="","", A$5) -> ภาควิชาวิศวกรรมอิเล็กทรอนิกส์และโทรคมนาคม
A20: 12 | B20: 69070502412 | D20: นายชวัลวัสถ์ ตรงศิริวัฒน์ | Z20: =IF(B20="","", A$5) -> ภาควิชาวิศวกรรมอิเล็กทรอนิกส์และโทรคมนาคม
... A68: 60 | B68: 69070502460 | D68: นางสาวอิสิริยา ดำริสม | Z68: =IF(B68="","", A$5) -> ภาควิชาวิศวกรรมอิเล็กทรอนิกส์และโทรคมนาคม
Z69: =IF(B69="","", A$5)
Z70: =IF(B70="","", A$5)
Z71: =IF(B71="","", A$5)
Z72: =IF(B72="","", A$5)
Z73: =IF(B73="","", A$5)
Z74: =IF(B74="","", A$5)
Z75: =IF(B75="","", A$5)
Z76: =IF(B76="","", A$5)
Z77: =IF(B77="","", A$5)
Z78: =IF(B78="","", A$5)
Z79: =IF(B79="","", A$5)
Z80: =IF(B80="","", A$5)
... Z1863: =IF(B1863="","", A$5)

Sheet 25540128 ชั้นปี 1(B) รุ่น 2569
A1: ระบบทะเบียน | C1: มหาวิทยาลัยเทคโนโลยีพระจอมเกล้าธนบุรี | J1: วันที่พิมพ์ : 25/06/2569
A2: 455024 | C2: รายงานรายชื่อนักศึกษาแยกตามชั้นปี
C3: ภาคการศึกษา : 3/2568
A4: ระดับปริญญาตรี | F4: คณะวิศวกรรมศาสตร์
A5: ภาควิชาวิศวกรรมอิเล็กทรอนิกส์และโทรคมนาคม | F5: สาขาวิชาวิศวกรรมไฟฟ้าสื่อสารและอิเล็กทรอนิกส์
A6: โครงการหลักสูตร 25540128 วิศวกรรมศาสตรบัณฑิต สาขาวิชาวิศวกรรมไฟฟ้าสื่อสารและอิเล็กทรอนิกส์ ปริญญาตรี 4 ปี
A7: ชั้นปี 1 รุ่นที่เข้าศึกษา 1/2569 ห้อง B อาจารย์ที่ปรึกษา ดร.ไพศาล สนธิกร, ดร.สาลินี ชูวิทย์สกุลเลิศ
A8: ลำดับ | B8: รหัสนักศึกษา | D8: ชื่อ-สกุล | H8: อาจารย์ที่ปรึกษาเฉพาะบุคคล
A9: 1 | B9: 69070502461 | D9: นางสาวกนกกร นิธิวิบูลย์ | Z9: =IF(B9="","", A$5) -> ภาควิชาวิศวกรรมอิเล็กทรอนิกส์และโทรคมนาคม
A10: 2 | B10: 69070502462 | D10: นางสาวกรกาญจน์ แนมจันทร์ | Z10: =IF(B10="","", A$5) -> ภาควิชาวิศวกรรมอิเล็กทรอนิกส์และโทรคมนาคม
A11: 3 | B11: 69070502463 | D11: นายกษิดิ์เดช เอี่ยมศิริ | Z11: =IF(B11="","", A$5) -> ภาควิชาวิศวกรรมอิเล็กทรอนิกส์และโทรคมนาคม
A12: 4 | B12: 69070502464 | D12: นางสาวกัญญาภัค อยู่ถมยา | Z12: =IF(B12="","", A$5) -> ภาควิชาวิศวกรรมอิเล็กทรอนิกส์และโทรคมนาคม
A13: 5 | B13: 69070502465 | D13: นายกันตพัฒน์ พงษ์สุวิเชษศักดิ์ | Z13: =IF(B13="","", A$5) -> ภาควิชาวิศวกรรมอิเล็กทรอนิกส์และโทรคมนาคม
A14: 6 | B14: 69070502466 | D14: นายกิตติศักดิ์ คำเอื้อย | Z14: =IF(B14="","", A$5) -> ภาควิชาวิศวกรรมอิเล็กทรอนิกส์และโทรคมนาคม
A15: 7 | B15: 69070502467 | D15: นายฉันท์ทีชย์ พิพัฒบวรนันท์ | Z15: =IF(B15="","", A$5) -> ภาควิชาวิศวกรรมอิเล็กทรอนิกส์และโทรคมนาคม
A16: 8 | B16: 69070502468 | D16: นางสาวชนาภา บุหรี่ทอง | Z16: =IF(B16="","", A$5) -> ภาควิชาวิศวกรรมอิเล็กทรอนิกส์และโทรคมนาคม
A17: 9 | B17: 69070502469 | D17: นายชลกฤษ หนูตอ | Z17: =IF(B17="","", A$5) -> ภาควิชาวิศวกรรมอิเล็กทรอนิกส์และโทรคมนาคม
A18: 10 | B18: 69070502470 | D18: นายชลชาติ อินทะขีณี | Z18: =IF(B18="","", A$5) -> ภาควิชาวิศวกรรมอิเล็กทรอนิกส์และโทรคมนาคม
A19: 11 | B19: 69070502471 | D19: นายโชคอนันต์ ซอนรัมย์ | Z19: =IF(B19="","", A$5) -> ภาควิชาวิศวกรรมอิเล็กทรอนิกส์และโทรคมนาคม
A20: 12 | B20: 69070502472 | D20: นางสาวญาณิศา ชัยจินดา | Z20: =IF(B20="","", A$5) -> ภาควิชาวิศวกรรมอิเล็กทรอนิกส์และโทรคมนาคม
... A69: 61 | B69: 69070502521 | D69: นายวริทธิ์นันท์ ธนะวงษ์ | Z69: =IF(B69="","", A$5) -> ภาควิชาวิศวกรรมอิเล็กทรอนิกส์และโทรคมนาคม
Z70: =IF(B70="","", A$5)
Z71: =IF(B71="","", A$5)
Z72: =IF(B72="","", A$5)
Z73: =IF(B73="","", A$5)
Z74: =IF(B74="","", A$5)
Z75: =IF(B75="","", A$5)
Z76: =IF(B76="","", A$5)
Z77: =IF(B77="","", A$5)
Z78: =IF(B78="","", A$5)
Z79: =IF(B79="","", A$5)
Z80: =IF(B80="","", A$5)
Z81: =IF(B81="","", A$5)
... Z1863: =IF(B1863="","", A$5)

Sheet 25540138 ชั้นปี 1(A) รุ่น 2569
A1: ระบบทะเบียน | C1: มหาวิทยาลัยเทคโนโลยีพระจอมเกล้าธนบุรี | J1: วันที่พิมพ์ : 25/06/2569
A2: 455024 | C2: รายงานรายชื่อนักศึกษาแยกตามชั้นปี
C3: ภาคการศึกษา : 3/2568
A4: ระดับปริญญาตรี | F4: คณะวิศวกรรมศาสตร์
A5: ภาควิชาวิศวกรรมเครื่องมือและวัสดุ | F5: สาขาวิชาวิศวกรรมวัสดุ
A6: โครงการหลักสูตร 25540138 วิศวกรรมศาสตรบัณฑิต สาขาวิชาวิศวกรรมวัสดุ ปริญญาตรี 4 ปี
A7: ชั้นปี 1 รุ่นที่เข้าศึกษา 1/2569 ห้อง A อาจารย์ที่ปรึกษา ดร.เจตนุพงศ์ พาโลมัส
A8: ลำดับ | B8: รหัสนักศึกษา | D8: ชื่อ-สกุล | H8: อาจารย์ที่ปรึกษาเฉพาะบุคคล
A9: 1 | B9: 69070501801 | D9: นายกฤตเมธ แซ่โง้ว | Z9: =IF(B9="","", A$5) -> ภาควิชาวิศวกรรมเครื่องมือและวัสดุ
A10: 2 | B10: 69070501802 | D10: นางสาวกัญญาภัค อัศวสรการ | Z10: =IF(B10="","", A$5) -> ภาควิชาวิศวกรรมเครื่องมือและวัสดุ
A11: 3 | B11: 69070501803 | D11: นายนิติภูมิ เชิดสูงเนิน | Z11: =IF(B11="","", A$5) -> ภาควิชาวิศวกรรมเครื่องมือและวัสดุ
A12: 4 | B12: 69070501804 | D12: นายพศวีร์ ปัญญาศรีวินิจ | Z12: =IF(B12="","", A$5) -> ภาควิชาวิศวกรรมเครื่องมือและวัสดุ
A13: 5 | B13: 69070501805 | D13: นายพัฒนายุทธ นงค์นวล | Z13: =IF(B13="","", A$5) -> ภาควิชาวิศวกรรมเครื่องมือและวัสดุ
A14: 6 | B14: 69070501806 | D14: นายภัชยะ รัตนวงศ์ | Z14: =IF(B14="","", A$5) -> ภาควิชาวิศวกรรมเครื่องมือและวัสดุ
A15: 7 | B15: 69070501807 | D15: นายสรวิศ สมุทรโคตา | Z15: =IF(B15="","", A$5) -> ภาควิชาวิศวกรรมเครื่องมือและวัสดุ
A16: 8 | B16: 69070501808 | D16: นางสาวสุภัสสร ตันวัฒนวิทย์ | Z16: =IF(B16="","", A$5) -> ภาควิชาวิศวกรรมเครื่องมือและวัสดุ
A17: 9 | B17: 69070501809 | D17: นางสาวชนากานต์ ธรรมวรีย์ | Z17: =IF(B17="","", A$5) -> ภาควิชาวิศวกรรมเครื่องมือและวัสดุ
A18: 10 | B18: 69070501810 | D18: นางสาวเชิญขวัญ คงปาน | Z18: =IF(B18="","", A$5) -> ภาควิชาวิศวกรรมเครื่องมือและวัสดุ
A19: 11 | B19: 69070501811 | D19: นายนพอนันต์ เนียลเซ็น | Z19: =IF(B19="","", A$5) -> ภาควิชาวิศวกรรมเครื่องมือและวัสดุ
A20: 12 | B20: 69070501812 | D20: นางสาวนภัทศรา ตระกูลศรี | Z20: =IF(B20="","", A$5) -> ภาควิชาวิศวกรรมเครื่องมือและวัสดุ
... A63: 55 | B63: 69070501855 | D63: นางสาวไอริสา ลิ้มพิริยะมงคล | Z63: =IF(B63="","", A$5) -> ภาควิชาวิศวกรรมเครื่องมือและวัสดุ
Z64: =IF(B64="","", A$5)
Z65: =IF(B65="","", A$5)
Z66: =IF(B66="","", A$5)
Z67: =IF(B67="","", A$5)
Z68: =IF(B68="","", A$5)
Z69: =IF(B69="","", A$5)
Z70: =IF(B70="","", A$5)
Z71: =IF(B71="","", A$5)
Z72: =IF(B72="","", A$5)
Z73: =IF(B73="","", A$5)
Z74: =IF(B74="","", A$5)
Z75: =IF(B75="","", A$5)
... Z1863: =IF(B1863="","", A$5)

Sheet 25540156 ชั้นปี 1(A) รุ่น 2569
A1: ระบบทะเบียน | C1: มหาวิทยาลัยเทคโนโลยีพระจอมเกล้าธนบุรี | J1: วันที่พิมพ์ : 25/06/2569
A2: 455024 | C2: รายงานรายชื่อนักศึกษาแยกตามชั้นปี
C3: ภาคการศึกษา : 3/2568
A4: ระดับปริญญาตรี | F4: คณะวิศวกรรมศาสตร์
A5: ภาควิชาวิศวกรรมไฟฟ้า | F5: สาขาวิชาวิศวกรรมไฟฟ้า
A6: โครงการหลักสูตร 25540156 วิศวกรรมศาสตรบัณฑิต สาขาวิชาวิศวกรรมไฟฟ้า (ระบบไฟฟ้า อิเล็กทรอนิกส์กำลัง และพลังงาน) ปริญญาตรี 4 ปี
A7: ชั้นปี 1 รุ่นที่เข้าศึกษา 1/2569 ห้อง A อาจารย์ที่ปรึกษา ผศ.ดร.ปิยสวัสดิ์ นวรัตน์ ณ อยุธยา
A8: ลำดับ | B8: รหัสนักศึกษา | D8: ชื่อ-สกุล | H8: อาจารย์ที่ปรึกษาเฉพาะบุคคล
A9: 1 | B9: 69070502801 | D9: นายกฤตภัค ลาภเจริญงาม | Z9: =IF(B9="","", A$5) -> ภาควิชาวิศวกรรมไฟฟ้า
A10: 2 | B10: 69070502802 | D10: นายกานต์ตะวัน สีชน | Z10: =IF(B10="","", A$5) -> ภาควิชาวิศวกรรมไฟฟ้า
A11: 3 | B11: 69070502803 | D11: นายชนาธิป ตันนิกร | Z11: =IF(B11="","", A$5) -> ภาควิชาวิศวกรรมไฟฟ้า
A12: 4 | B12: 69070502804 | D12: นายญาณภัทร ภิญโญ | Z12: =IF(B12="","", A$5) -> ภาควิชาวิศวกรรมไฟฟ้า
A13: 5 | B13: 69070502805 | D13: นายณัฐวรรธน์ มั่งสูงเนิน | Z13: =IF(B13="","", A$5) -> ภาควิชาวิศวกรรมไฟฟ้า
A14: 6 | B14: 69070502806 | D14: นางสาวดลรดา รัตนรักษ์ | Z14: =IF(B14="","", A$5) -> ภาควิชาวิศวกรรมไฟฟ้า
A15: 7 | B15: 69070502807 | D15: นายเตชทัต ศรีมันตะ | Z15: =IF(B15="","", A$5) -> ภาควิชาวิศวกรรมไฟฟ้า
A16: 8 | B16: 69070502808 | D16: นายธนโชติ สารศิริ | Z16: =IF(B16="","", A$5) -> ภาควิชาวิศวกรรมไฟฟ้า
A17: 9 | B17: 69070502809 | D17: นางสาวธัญญพัฒน์ พุทธโกมล | Z17: =IF(B17="","", A$5) -> ภาควิชาวิศวกรรมไฟฟ้า
